2018-07-10 13:46:26,948 (47911/MainThread) pgcli.main INFO - Default pager found in PAGER environment variable: "less"
2018-07-10 13:53:05,937 (47911/MainThread) pgcli.pgexecute ERROR - sql: u"select count(1) from experiment_logs el inner join subscriptions s on el.user_id = s.user_id inner join subscription_plans ON subscription_plans.id = s.subscription_plan_id where el.experiment = '1-CTA-vs-2-CTA-on-homepage-header-80-20' and sp.profile_type = 1", error: ProgrammingError('missing FROM-clause entry for table "sp"\nLINE 1: ...t = \'1-CTA-vs-2-CTA-on-homepage-header-80-20\' and sp.profile...\n                                                             ^\n',)
2018-07-10 13:53:05,938 (47911/MainThread) pgcli.pgexecute ERROR - traceback: 'Traceback (most recent call last):\n  File "/usr/local/Cellar/pgcli/1.9.1/libexec/lib/python2.7/site-packages/pgcli/pgexecute.py", line 319, in run\n    yield self.execute_normal_sql(sql) + (sql, True)\n  File "/usr/local/Cellar/pgcli/1.9.1/libexec/lib/python2.7/site-packages/pgcli/pgexecute.py", line 355, in execute_normal_sql\n    cur.execute(split_sql)\nProgrammingError: missing FROM-clause entry for table "sp"\nLINE 1: ...t = \'1-CTA-vs-2-CTA-on-homepage-header-80-20\' and sp.profile...\n                                                             ^\n\n'
2018-07-10 13:56:25,878 (47911/MainThread) pgcli.pgexecute ERROR - sql: u"select count(1) from experiment_logs el inner join subscriptions s on el.user_id = s.user_id inner join subscription_plans ON subscription_plans.id = s.subscription_plan_id where el.experiment = '1-CTA-vs-2-CTA-on-homepage-header-80-20' and el.variant = 'control' and sp.profile_type = 1", error: ProgrammingError('missing FROM-clause entry for table "sp"\nLINE 1: ...page-header-80-20\' and el.variant = \'control\' and sp.profile...\n                                                             ^\n',)
2018-07-10 13:56:25,878 (47911/MainThread) pgcli.pgexecute ERROR - traceback: 'Traceback (most recent call last):\n  File "/usr/local/Cellar/pgcli/1.9.1/libexec/lib/python2.7/site-packages/pgcli/pgexecute.py", line 319, in run\n    yield self.execute_normal_sql(sql) + (sql, True)\n  File "/usr/local/Cellar/pgcli/1.9.1/libexec/lib/python2.7/site-packages/pgcli/pgexecute.py", line 355, in execute_normal_sql\n    cur.execute(split_sql)\nProgrammingError: missing FROM-clause entry for table "sp"\nLINE 1: ...page-header-80-20\' and el.variant = \'control\' and sp.profile...\n                                                             ^\n\n'
2018-07-17 11:22:58,484 (19809/MainThread) pgcli.main INFO - Default pager found in PAGER environment variable: "less"
2018-07-17 11:23:06,050 (19809/MainThread) pgcli.pgexecute ERROR - sql: u'select * from company_adm', error: ProgrammingError('relation "company_adm" does not exist\nLINE 1: select * from company_adm\n                      ^\n',)
2018-07-17 11:23:06,050 (19809/MainThread) pgcli.pgexecute ERROR - traceback: 'Traceback (most recent call last):\n  File "/usr/local/Cellar/pgcli/1.9.1/libexec/lib/python2.7/site-packages/pgcli/pgexecute.py", line 319, in run\n    yield self.execute_normal_sql(sql) + (sql, True)\n  File "/usr/local/Cellar/pgcli/1.9.1/libexec/lib/python2.7/site-packages/pgcli/pgexecute.py", line 355, in execute_normal_sql\n    cur.execute(split_sql)\nProgrammingError: relation "company_adm" does not exist\nLINE 1: select * from company_adm\n                      ^\n\n'
2018-07-20 14:16:01,190 (64325/MainThread) pgcli.main INFO - Default pager found in PAGER environment variable: "less"
2018-07-20 14:16:40,598 (64325/MainThread) pgcli.pgexecute ERROR - sql: u'select * from experiments limit 10', error: ProgrammingError('relation "experiments" does not exist\nLINE 1: select * from experiments limit 10\n                      ^\n',)
2018-07-20 14:16:40,599 (64325/MainThread) pgcli.pgexecute ERROR - traceback: 'Traceback (most recent call last):\n  File "/usr/local/Cellar/pgcli/1.9.1/libexec/lib/python2.7/site-packages/pgcli/pgexecute.py", line 319, in run\n    yield self.execute_normal_sql(sql) + (sql, True)\n  File "/usr/local/Cellar/pgcli/1.9.1/libexec/lib/python2.7/site-packages/pgcli/pgexecute.py", line 355, in execute_normal_sql\n    cur.execute(split_sql)\nProgrammingError: relation "experiments" does not exist\nLINE 1: select * from experiments limit 10\n                      ^\n\n'
2018-07-20 14:17:24,342 (64325/MainThread) pgcli.pgexecute ERROR - sql: u'select group(experiment) from experiment_logs limit 10', error: ProgrammingError('syntax error at or near "("\nLINE 1: select group(experiment) from experiment_logs limit 10\n                    ^\n',)
2018-07-20 14:17:24,343 (64325/MainThread) pgcli.pgexecute ERROR - traceback: 'Traceback (most recent call last):\n  File "/usr/local/Cellar/pgcli/1.9.1/libexec/lib/python2.7/site-packages/pgcli/pgexecute.py", line 319, in run\n    yield self.execute_normal_sql(sql) + (sql, True)\n  File "/usr/local/Cellar/pgcli/1.9.1/libexec/lib/python2.7/site-packages/pgcli/pgexecute.py", line 355, in execute_normal_sql\n    cur.execute(split_sql)\nProgrammingError: syntax error at or near "("\nLINE 1: select group(experiment) from experiment_logs limit 10\n                    ^\n\n'
2018-07-20 14:17:49,229 (64325/MainThread) pgcli.pgexecute ERROR - sql: u'select experiment from experiment_logs group by experiment order by experiment_id desc limit 100', error: ProgrammingError('column "experiment_id" does not exist\nLINE 1: ...from experiment_logs group by experiment order by experiment...\n                                                             ^\n',)
2018-07-20 14:17:49,230 (64325/MainThread) pgcli.pgexecute ERROR - traceback: 'Traceback (most recent call last):\n  File "/usr/local/Cellar/pgcli/1.9.1/libexec/lib/python2.7/site-packages/pgcli/pgexecute.py", line 319, in run\n    yield self.execute_normal_sql(sql) + (sql, True)\n  File "/usr/local/Cellar/pgcli/1.9.1/libexec/lib/python2.7/site-packages/pgcli/pgexecute.py", line 355, in execute_normal_sql\n    cur.execute(split_sql)\nProgrammingError: column "experiment_id" does not exist\nLINE 1: ...from experiment_logs group by experiment order by experiment...\n                                                             ^\n\n'
2018-07-20 14:17:54,278 (64325/MainThread) pgcli.pgexecute ERROR - sql: u'select experiment from experiment_logs group by experiment order by id desc limit 100', error: ProgrammingError('column "experiment_logs.id" must appear in the GROUP BY clause or be used in an aggregate function\nLINE 1: ...from experiment_logs group by experiment order by id desc li...\n                                                             ^\n',)
2018-07-20 14:17:54,278 (64325/MainThread) pgcli.pgexecute ERROR - traceback: 'Traceback (most recent call last):\n  File "/usr/local/Cellar/pgcli/1.9.1/libexec/lib/python2.7/site-packages/pgcli/pgexecute.py", line 319, in run\n    yield self.execute_normal_sql(sql) + (sql, True)\n  File "/usr/local/Cellar/pgcli/1.9.1/libexec/lib/python2.7/site-packages/pgcli/pgexecute.py", line 355, in execute_normal_sql\n    cur.execute(split_sql)\nProgrammingError: column "experiment_logs.id" must appear in the GROUP BY clause or be used in an aggregate function\nLINE 1: ...from experiment_logs group by experiment order by id desc li...\n                                                             ^\n\n'
2018-07-20 14:18:05,096 (64325/MainThread) pgcli.pgexecute ERROR - sql: u'select experiment from experiment_logs group by experiment desc limit 100', error: ProgrammingError('syntax error at or near "desc"\nLINE 1: ...periment from experiment_logs group by experiment desc limit...\n                                                             ^\n',)
2018-07-20 14:18:05,096 (64325/MainThread) pgcli.pgexecute ERROR - traceback: 'Traceback (most recent call last):\n  File "/usr/local/Cellar/pgcli/1.9.1/libexec/lib/python2.7/site-packages/pgcli/pgexecute.py", line 319, in run\n    yield self.execute_normal_sql(sql) + (sql, True)\n  File "/usr/local/Cellar/pgcli/1.9.1/libexec/lib/python2.7/site-packages/pgcli/pgexecute.py", line 355, in execute_normal_sql\n    cur.execute(split_sql)\nProgrammingError: syntax error at or near "desc"\nLINE 1: ...periment from experiment_logs group by experiment desc limit...\n                                                             ^\n\n'
2018-07-23 16:46:58,991 (71614/MainThread) pgcli.main INFO - Default pager found in PAGER environment variable: "less"
2018-07-25 16:21:03,222 (94291/MainThread) pgcli.main INFO - Default pager found in PAGER environment variable: "less"
2018-07-25 16:23:00,873 (94291/MainThread) pgcli.pgexecute ERROR - sql: u'select * from count', error: ProgrammingError('relation "count" does not exist\nLINE 1: select * from count\n                      ^\n',)
2018-07-25 16:23:00,873 (94291/MainThread) pgcli.pgexecute ERROR - traceback: 'Traceback (most recent call last):\n  File "/usr/local/Cellar/pgcli/1.9.1/libexec/lib/python2.7/site-packages/pgcli/pgexecute.py", line 319, in run\n    yield self.execute_normal_sql(sql) + (sql, True)\n  File "/usr/local/Cellar/pgcli/1.9.1/libexec/lib/python2.7/site-packages/pgcli/pgexecute.py", line 355, in execute_normal_sql\n    cur.execute(split_sql)\nProgrammingError: relation "count" does not exist\nLINE 1: select * from count\n                      ^\n\n'
2018-07-26 14:28:13,036 (94291/MainThread) pgcli.pgexecute ERROR - sql: u'select v.id from verifications v left outer join verifications_address_verifications vav on v.id = vav.verification_id left outer join verifications_phone_verifications vpv on v.id = vpv.verification_id where v.state = 0 and (vav.id is null or vpv.id is null) limit 10', error: ProgrammingError('relation "verifications_address_verifications" does not exist\nLINE 1: select v.id from verifications v left outer join verificatio...\n                                                         ^\n',)
2018-07-26 14:28:13,037 (94291/MainThread) pgcli.pgexecute ERROR - traceback: 'Traceback (most recent call last):\n  File "/usr/local/Cellar/pgcli/1.9.1/libexec/lib/python2.7/site-packages/pgcli/pgexecute.py", line 319, in run\n    yield self.execute_normal_sql(sql) + (sql, True)\n  File "/usr/local/Cellar/pgcli/1.9.1/libexec/lib/python2.7/site-packages/pgcli/pgexecute.py", line 355, in execute_normal_sql\n    cur.execute(split_sql)\nProgrammingError: relation "verifications_address_verifications" does not exist\nLINE 1: select v.id from verifications v left outer join verificatio...\n                                                         ^\n\n'
2018-07-26 14:56:02,023 (94291/MainThread) pgcli.pgexecute ERROR - sql: u'select * from verifications where id id NOT IN (\n        SELECT id FROM verifications v\n        WHERE user_id IN (\n          SELECT user_id\n          FROM verifications\n          WHERE state = 0\n          GROUP BY user_id\n          HAVING COUNT(1) > 1\n        )\n        ORDER BY updated_at DESC\n        LIMIT 1\n      )\n      AND id IN (\n        SELECT id FROM verifications v\n        WHERE user_id IN (\n          SELECT user_id\n          FROM verifications\n          WHERE state = 0\n          GROUP BY user_id\n          HAVING COUNT(1) > 1\n        )\n      )', error: ProgrammingError('syntax error at or near "id"\nLINE 1: select * from verifications where id id NOT IN (\n                                             ^\n',)
2018-07-26 14:56:02,023 (94291/MainThread) pgcli.pgexecute ERROR - traceback: 'Traceback (most recent call last):\n  File "/usr/local/Cellar/pgcli/1.9.1/libexec/lib/python2.7/site-packages/pgcli/pgexecute.py", line 319, in run\n    yield self.execute_normal_sql(sql) + (sql, True)\n  File "/usr/local/Cellar/pgcli/1.9.1/libexec/lib/python2.7/site-packages/pgcli/pgexecute.py", line 355, in execute_normal_sql\n    cur.execute(split_sql)\nProgrammingError: syntax error at or near "id"\nLINE 1: select * from verifications where id id NOT IN (\n                                             ^\n\n'
2018-07-26 14:58:22,406 (94291/MainThread) pgcli.pgexecute ERROR - sql: u'select * from verifications where id NOT IN (\n        SELECT id FROM verifications v\n        WHERE user_id IN (\n          SELECT user_id\n          FROM verifications\n          WHERE state = 0\n          GROUP BY user_id\n          HAVING COUNT(1) > 1\n        )\n        ORDER BY updated_at DESC\n        LIMIT 1\n      )\n      AND id IN (\n        SELECT id FROM verifications v\n        INNER JOIN verification_address_verifications vav ON v.id = vav.verification_id\n        INNER JOIN verification_phone_verifications vpv ON v.id = vpv.verification_id\n        WHERE user_id IN (\n          SELECT user_id\n          FROM verifications\n          WHERE state = 0\n          GROUP BY user_id\n          HAVING COUNT(1) > 1\n        )\n      )', error: ProgrammingError('column reference "id" is ambiguous\nLINE 14:         SELECT id FROM verifications v\n                        ^\n',)
2018-07-26 14:58:22,406 (94291/MainThread) pgcli.pgexecute ERROR - traceback: 'Traceback (most recent call last):\n  File "/usr/local/Cellar/pgcli/1.9.1/libexec/lib/python2.7/site-packages/pgcli/pgexecute.py", line 319, in run\n    yield self.execute_normal_sql(sql) + (sql, True)\n  File "/usr/local/Cellar/pgcli/1.9.1/libexec/lib/python2.7/site-packages/pgcli/pgexecute.py", line 355, in execute_normal_sql\n    cur.execute(split_sql)\nProgrammingError: column reference "id" is ambiguous\nLINE 14:         SELECT id FROM verifications v\n                        ^\n\n'
2018-07-26 15:09:09,574 (94291/MainThread) pgcli.pgexecute ERROR - sql: u'`select user_id, count(1) from verifications where state = 0 group by user_id having count(1) > 1', error: ProgrammingError('syntax error at or near "`"\nLINE 1: `select user_id, count(1) from verifications where state = 0...\n        ^\n',)
2018-07-26 15:09:09,575 (94291/MainThread) pgcli.pgexecute ERROR - traceback: 'Traceback (most recent call last):\n  File "/usr/local/Cellar/pgcli/1.9.1/libexec/lib/python2.7/site-packages/pgcli/pgexecute.py", line 319, in run\n    yield self.execute_normal_sql(sql) + (sql, True)\n  File "/usr/local/Cellar/pgcli/1.9.1/libexec/lib/python2.7/site-packages/pgcli/pgexecute.py", line 355, in execute_normal_sql\n    cur.execute(split_sql)\nProgrammingError: syntax error at or near "`"\nLINE 1: `select user_id, count(1) from verifications where state = 0...\n        ^\n\n'
2018-07-26 15:20:18,791 (94291/MainThread) pgcli.pgexecute ERROR - sql: u'UPDATE verifications v SET state = 2\n      FROM verification_address_verifications vav\n      LEFT OUTER JOIN verification_phone_verifications vpv ON v.id = vpv.verification_id\n      WHERE v.id = vav.verification_id\n      WHERE ((vav.id IS NULL AND vpv.id IS NULL)\n        OR (vav.id IS NOT NULL AND vpv.id IS NULL)\n        OR (vav.id IS NULL AND vpv.id IS NOT NULL))\n      AND v.user_id IN (\n        SELECT user_id\n        FROM verifications\n        WHERE state = 0\n        GROUP BY user_id\n        HAVING COUNT(1) > 1\n      )', error: ProgrammingError('syntax error at or near "WHERE"\nLINE 5:       WHERE ((vav.id IS NULL AND vpv.id IS NULL)\n              ^\n',)
2018-07-26 15:20:18,793 (94291/MainThread) pgcli.pgexecute ERROR - traceback: 'Traceback (most recent call last):\n  File "/usr/local/Cellar/pgcli/1.9.1/libexec/lib/python2.7/site-packages/pgcli/pgexecute.py", line 319, in run\n    yield self.execute_normal_sql(sql) + (sql, True)\n  File "/usr/local/Cellar/pgcli/1.9.1/libexec/lib/python2.7/site-packages/pgcli/pgexecute.py", line 355, in execute_normal_sql\n    cur.execute(split_sql)\nProgrammingError: syntax error at or near "WHERE"\nLINE 5:       WHERE ((vav.id IS NULL AND vpv.id IS NULL)\n              ^\n\n'
2018-07-26 15:20:31,964 (94291/MainThread) pgcli.pgexecute ERROR - sql: u'UPDATE verifications v SET state = 2\n      FROM verification_address_verifications vav\n      LEFT OUTER JOIN verification_phone_verifications vpv ON v.id = vpv.verification_id\n      WHERE v.id = vav.verification_id\n      AND ((vav.id IS NULL AND vpv.id IS NULL)\n        OR (vav.id IS NOT NULL AND vpv.id IS NULL)\n        OR (vav.id IS NULL AND vpv.id IS NOT NULL))\n      AND v.user_id IN (\n        SELECT user_id\n        FROM verifications\n        WHERE state = 0\n        GROUP BY user_id\n        HAVING COUNT(1) > 1\n      )', error: ProgrammingError('invalid reference to FROM-clause entry for table "v"\nLINE 3: ...UTER JOIN verification_phone_verifications vpv ON v.id = vpv...\n                                                             ^\nHINT:  There is an entry for table "v", but it cannot be referenced from this part of the query.\n',)
2018-07-26 15:20:31,965 (94291/MainThread) pgcli.pgexecute ERROR - traceback: 'Traceback (most recent call last):\n  File "/usr/local/Cellar/pgcli/1.9.1/libexec/lib/python2.7/site-packages/pgcli/pgexecute.py", line 319, in run\n    yield self.execute_normal_sql(sql) + (sql, True)\n  File "/usr/local/Cellar/pgcli/1.9.1/libexec/lib/python2.7/site-packages/pgcli/pgexecute.py", line 355, in execute_normal_sql\n    cur.execute(split_sql)\nProgrammingError: invalid reference to FROM-clause entry for table "v"\nLINE 3: ...UTER JOIN verification_phone_verifications vpv ON v.id = vpv...\n                                                             ^\nHINT:  There is an entry for table "v", but it cannot be referenced from this part of the query.\n\n'
2018-07-26 15:51:21,184 (94291/MainThread) pgcli.pgexecute ERROR - sql: u'select vav.verified = 1 and vpv.verified = 1 as verified from users u inner join verifications v on u.id = v.user_id inner join verification_address_verifications vav on v.id = vav.verification_id inner join verification_phone_verifications vpv on v.id = vpv.verification_id order by random() limit 10', error: ProgrammingError('operator does not exist: boolean = integer\nLINE 1: select vav.verified = 1 and vpv.verified = 1 as verified fro...\n                            ^\nHINT:  No operator matches the given name and argument type(s). You might need to add explicit type casts.\n',)
2018-07-26 15:51:21,185 (94291/MainThread) pgcli.pgexecute ERROR - traceback: 'Traceback (most recent call last):\n  File "/usr/local/Cellar/pgcli/1.9.1/libexec/lib/python2.7/site-packages/pgcli/pgexecute.py", line 319, in run\n    yield self.execute_normal_sql(sql) + (sql, True)\n  File "/usr/local/Cellar/pgcli/1.9.1/libexec/lib/python2.7/site-packages/pgcli/pgexecute.py", line 355, in execute_normal_sql\n    cur.execute(split_sql)\nProgrammingError: operator does not exist: boolean = integer\nLINE 1: select vav.verified = 1 and vpv.verified = 1 as verified fro...\n                            ^\nHINT:  No operator matches the given name and argument type(s). You might need to add explicit type casts.\n\n'
2018-07-26 16:36:05,943 (94291/MainThread) pgcli.pgexecute ERROR - sql: u"SELECT u.firstname, u.surname, u.email, v.id, v.state, vav.verified, vpv.verified\n      FROM users u\n      INNER JOIN subscriptions s ON u.id = s.user_id AND s.created_at BETWEEN '2018-06-01' and '2018-06-30'\n      LEFT OUTER JOIN verifications v ON u.id = v.user_id AND v.state = 0\n      LEFT OUTER JOIN verification_address_verifications vav ON v.id = vav.verification_id AND v.verified = TRUE\n      LEFT OUTER JOIN verification_phone_verifications vpv ON v.id = vpv.verification_id AND v.verified = TRUE\n      WHERE v.id IS NULL OR vav.id IS NULL OR vpv.id IS NULL", error: ProgrammingError('column v.verified does not exist\nLINE 5: ...rifications vav ON v.id = vav.verification_id AND v.verified...\n                                                             ^\n',)
2018-07-26 16:36:05,944 (94291/MainThread) pgcli.pgexecute ERROR - traceback: 'Traceback (most recent call last):\n  File "/usr/local/Cellar/pgcli/1.9.1/libexec/lib/python2.7/site-packages/pgcli/pgexecute.py", line 319, in run\n    yield self.execute_normal_sql(sql) + (sql, True)\n  File "/usr/local/Cellar/pgcli/1.9.1/libexec/lib/python2.7/site-packages/pgcli/pgexecute.py", line 355, in execute_normal_sql\n    cur.execute(split_sql)\nProgrammingError: column v.verified does not exist\nLINE 5: ...rifications vav ON v.id = vav.verification_id AND v.verified...\n                                                             ^\n\n'
2018-07-30 10:24:37,595 (2972/MainThread) pgcli.main INFO - Default pager found in PAGER environment variable: "less"
2018-07-30 10:24:52,622 (2972/MainThread) pgcli.pgexecute ERROR - sql: u'select count(1) from verifications where verified = 1', error: ProgrammingError('column "verified" does not exist\nLINE 1: select count(1) from verifications where verified = 1\n                                                 ^\n',)
2018-07-30 10:24:52,623 (2972/MainThread) pgcli.pgexecute ERROR - traceback: 'Traceback (most recent call last):\n  File "/usr/local/Cellar/pgcli/1.9.1/libexec/lib/python2.7/site-packages/pgcli/pgexecute.py", line 319, in run\n    yield self.execute_normal_sql(sql) + (sql, True)\n  File "/usr/local/Cellar/pgcli/1.9.1/libexec/lib/python2.7/site-packages/pgcli/pgexecute.py", line 355, in execute_normal_sql\n    cur.execute(split_sql)\nProgrammingError: column "verified" does not exist\nLINE 1: select count(1) from verifications where verified = 1\n                                                 ^\n\n'
2018-07-30 10:25:14,171 (2972/MainThread) pgcli.pgexecute ERROR - sql: u'select count(1) from verification_address_verifications where verified = 1', error: ProgrammingError('operator does not exist: boolean = integer\nLINE 1: ...) from verification_address_verifications where verified = 1\n                                                                    ^\nHINT:  No operator matches the given name and argument type(s). You might need to add explicit type casts.\n',)
2018-07-30 10:25:14,172 (2972/MainThread) pgcli.pgexecute ERROR - traceback: 'Traceback (most recent call last):\n  File "/usr/local/Cellar/pgcli/1.9.1/libexec/lib/python2.7/site-packages/pgcli/pgexecute.py", line 319, in run\n    yield self.execute_normal_sql(sql) + (sql, True)\n  File "/usr/local/Cellar/pgcli/1.9.1/libexec/lib/python2.7/site-packages/pgcli/pgexecute.py", line 355, in execute_normal_sql\n    cur.execute(split_sql)\nProgrammingError: operator does not exist: boolean = integer\nLINE 1: ...) from verification_address_verifications where verified = 1\n                                                                    ^\nHINT:  No operator matches the given name and argument type(s). You might need to add explicit type casts.\n\n'
2018-07-31 13:59:23,498 (28672/MainThread) pgcli.main INFO - Default pager found in PAGER environment variable: "less"
2018-08-01 11:13:12,231 (28672/MainThread) pgcli.pgexecute ERROR - sql: u"select\n  u.created_at::date,\n  count(case when round(s.created_at - u.created_at) = 1 then 1 else 0 end) as sub_count\nfrom\n  users u\n  inner join subscriptions s on u.id = s.user_id\nwhere u.created_at between '2018-05-01' and '2018-05-31'\ngroup by\n  u.created_at::date\norder by u.created_at::date\nlimit 10", error: ProgrammingError('function round(interval) does not exist\nLINE 3:   count(case when round(s.created_at - u.created_at) = 1 the...\n                          ^\nHINT:  No function matches the given name and argument types. You might need to add explicit type casts.\n',)
2018-08-01 11:13:12,235 (28672/MainThread) pgcli.pgexecute ERROR - traceback: 'Traceback (most recent call last):\n  File "/usr/local/Cellar/pgcli/1.9.1/libexec/lib/python2.7/site-packages/pgcli/pgexecute.py", line 319, in run\n    yield self.execute_normal_sql(sql) + (sql, True)\n  File "/usr/local/Cellar/pgcli/1.9.1/libexec/lib/python2.7/site-packages/pgcli/pgexecute.py", line 355, in execute_normal_sql\n    cur.execute(split_sql)\nProgrammingError: function round(interval) does not exist\nLINE 3:   count(case when round(s.created_at - u.created_at) = 1 the...\n                          ^\nHINT:  No function matches the given name and argument types. You might need to add explicit type casts.\n\n'
2018-08-01 11:15:02,191 (28672/MainThread) pgcli.pgexecute ERROR - sql: u"select\n  u.created_at::date,\n  count(case when date_trunc('day', s.created_at - u.created_at) = 1 then 1 else 0 end) as sub_count\nfrom\n  users u\n  inner join subscriptions s on u.id = s.user_id\nwhere u.created_at between '2018-05-01' and '2018-05-31'\ngroup by\n  u.created_at::date\norder by u.created_at::date\nlimit 10", error: ProgrammingError("operator does not exist: interval = integer\nLINE 3: ...en date_trunc('day', s.created_at - u.created_at) = 1 then 1...\n                                                             ^\nHINT:  No operator matches the given name and argument type(s). You might need to add explicit type casts.\n",)
2018-08-01 11:15:02,191 (28672/MainThread) pgcli.pgexecute ERROR - traceback: 'Traceback (most recent call last):\n  File "/usr/local/Cellar/pgcli/1.9.1/libexec/lib/python2.7/site-packages/pgcli/pgexecute.py", line 319, in run\n    yield self.execute_normal_sql(sql) + (sql, True)\n  File "/usr/local/Cellar/pgcli/1.9.1/libexec/lib/python2.7/site-packages/pgcli/pgexecute.py", line 355, in execute_normal_sql\n    cur.execute(split_sql)\nProgrammingError: operator does not exist: interval = integer\nLINE 3: ...en date_trunc(\'day\', s.created_at - u.created_at) = 1 then 1...\n                                                             ^\nHINT:  No operator matches the given name and argument type(s). You might need to add explicit type casts.\n\n'
2018-08-01 11:15:48,846 (28672/MainThread) pgcli.pgexecute ERROR - sql: u"select\n  u.created_at::date,\n  count(case when date_trunc('day', s.created_at - u.created_at)::int = 1 then 1 else 0 end) as sub_count\nfrom\n  users u\n  inner join subscriptions s on u.id = s.user_id\nwhere u.created_at between '2018-05-01' and '2018-05-31'\ngroup by\n  u.created_at::date\norder by u.created_at::date\nlimit 10", error: ProgrammingError("cannot cast type interval to integer\nLINE 3: ...hen date_trunc('day', s.created_at - u.created_at)::int = 1 ...\n                                                             ^\n",)
2018-08-01 11:15:48,847 (28672/MainThread) pgcli.pgexecute ERROR - traceback: 'Traceback (most recent call last):\n  File "/usr/local/Cellar/pgcli/1.9.1/libexec/lib/python2.7/site-packages/pgcli/pgexecute.py", line 319, in run\n    yield self.execute_normal_sql(sql) + (sql, True)\n  File "/usr/local/Cellar/pgcli/1.9.1/libexec/lib/python2.7/site-packages/pgcli/pgexecute.py", line 355, in execute_normal_sql\n    cur.execute(split_sql)\nProgrammingError: cannot cast type interval to integer\nLINE 3: ...hen date_trunc(\'day\', s.created_at - u.created_at)::int = 1 ...\n                                                             ^\n\n'
2018-08-01 11:17:28,977 (28672/MainThread) pgcli.pgexecute ERROR - sql: u"select\n  u.created_at::date,\n  count(case when extract('day', date_trunc('day', s.created_at - u.created_at)) = 1 then 1 else 0 end) as sub_count\nfrom\n  users u\n  inner join subscriptions s on u.id = s.user_id\nwhere u.created_at between '2018-05-01' and '2018-05-31'\ngroup by\n  u.created_at::date\norder by u.created_at::date\nlimit 10", error: ProgrammingError('syntax error at or near ","\nLINE 3:   count(case when extract(\'day\', date_trunc(\'day\', s.created...\n                                       ^\n',)
2018-08-01 11:17:28,977 (28672/MainThread) pgcli.pgexecute ERROR - traceback: 'Traceback (most recent call last):\n  File "/usr/local/Cellar/pgcli/1.9.1/libexec/lib/python2.7/site-packages/pgcli/pgexecute.py", line 319, in run\n    yield self.execute_normal_sql(sql) + (sql, True)\n  File "/usr/local/Cellar/pgcli/1.9.1/libexec/lib/python2.7/site-packages/pgcli/pgexecute.py", line 355, in execute_normal_sql\n    cur.execute(split_sql)\nProgrammingError: syntax error at or near ","\nLINE 3:   count(case when extract(\'day\', date_trunc(\'day\', s.created...\n                                       ^\n\n'
2018-08-01 11:29:13,931 (28672/MainThread) pgcli.pgexecute ERROR - sql: u"select\n  u.created_at::date,\n  date_trunc('day', u.created_at) as substart,\n  date_trunc('day', u.created_at) + interval'1 day' as subend\nfrom users u\nwhere u.created_at between '2018-05-01' and '2018-05-31'\ngroup by\n  u.created_at::date", error: ProgrammingError('column "u.created_at" must appear in the GROUP BY clause or be used in an aggregate function\nLINE 3:   date_trunc(\'day\', u.created_at) as substart,\n                            ^\n',)
2018-08-01 11:29:13,932 (28672/MainThread) pgcli.pgexecute ERROR - traceback: 'Traceback (most recent call last):\n  File "/usr/local/Cellar/pgcli/1.9.1/libexec/lib/python2.7/site-packages/pgcli/pgexecute.py", line 319, in run\n    yield self.execute_normal_sql(sql) + (sql, True)\n  File "/usr/local/Cellar/pgcli/1.9.1/libexec/lib/python2.7/site-packages/pgcli/pgexecute.py", line 355, in execute_normal_sql\n    cur.execute(split_sql)\nProgrammingError: column "u.created_at" must appear in the GROUP BY clause or be used in an aggregate function\nLINE 3:   date_trunc(\'day\', u.created_at) as substart,\n                            ^\n\n'
2018-08-01 11:33:01,301 (28672/MainThread) pgcli.pgexecute ERROR - sql: u"select\n  u.created_at::date,\n  count(s.id) as sub_count\nfrom users u\nleft outer join subscriptions s on s.created_at between u.created_at and (u.created_at + interval'1 day')\nwhere u.created_at between '2018-05-01' and '2018-05-31'\ngroup by\n  u.created_at::date\norder by u.created_at::date\nlimit 10", error: QueryCanceledError('canceling statement due to user request\n',)
2018-08-01 11:33:01,302 (28672/MainThread) pgcli.pgexecute ERROR - traceback: 'Traceback (most recent call last):\n  File "/usr/local/Cellar/pgcli/1.9.1/libexec/lib/python2.7/site-packages/pgcli/pgexecute.py", line 319, in run\n    yield self.execute_normal_sql(sql) + (sql, True)\n  File "/usr/local/Cellar/pgcli/1.9.1/libexec/lib/python2.7/site-packages/pgcli/pgexecute.py", line 355, in execute_normal_sql\n    cur.execute(split_sql)\nQueryCanceledError: canceling statement due to user request\n\n'
2018-08-01 11:33:01,302 (28672/MainThread) pgcli.main ERROR - sql: u"select\n  u.created_at::date,\n  count(s.id) as sub_count\nfrom users u\nleft outer join subscriptions s on s.created_at between u.created_at and (u.created_at + interval'1 day')\nwhere u.created_at between '2018-05-01' and '2018-05-31'\ngroup by\n  u.created_at::date\norder by u.created_at::date\nlimit 10;", error: QueryCanceledError('canceling statement due to user request\n',)
2018-08-01 11:33:01,304 (28672/MainThread) pgcli.main ERROR - traceback: 'Traceback (most recent call last):\n  File "/usr/local/Cellar/pgcli/1.9.1/libexec/lib/python2.7/site-packages/pgcli/main.py", line 462, in execute_command\n    output, query = self._evaluate_command(text)\n  File "/usr/local/Cellar/pgcli/1.9.1/libexec/lib/python2.7/site-packages/pgcli/main.py", line 685, in _evaluate_command\n    for title, cur, headers, status, sql, success in res:\n  File "/usr/local/Cellar/pgcli/1.9.1/libexec/lib/python2.7/site-packages/pgcli/pgexecute.py", line 319, in run\n    yield self.execute_normal_sql(sql) + (sql, True)\n  File "/usr/local/Cellar/pgcli/1.9.1/libexec/lib/python2.7/site-packages/pgcli/pgexecute.py", line 355, in execute_normal_sql\n    cur.execute(split_sql)\nQueryCanceledError: canceling statement due to user request\n\n'
2018-08-01 11:45:46,631 (28672/MainThread) pgcli.pgexecute ERROR - sql: u"select\n  u.created_at::date,\n  count(s.id) as sub_count,\n  sum(case when s.profile_type = 0 then 1 else 0 end) as borrower_count,\n  sum(case when s.profile_type = 1 then 1 else 0 end) as owner_count,\n  count(u.id) as reg_count\nfrom users u\nleft outer join subscriptions s on u.id = s.user_id and s.created_at between u.created_at and (u.created_at + interval'1 day')\nwhere u.created_at between '2018-05-01' and '2018-05-31'\ngroup by\n  u.created_at::date\norder by u.created_at::date\nlimit 10", error: ProgrammingError('column s.profile_type does not exist\nLINE 4:   sum(case when s.profile_type = 0 then 1 else 0 end) as bor...\n                        ^\n',)
2018-08-01 11:45:46,631 (28672/MainThread) pgcli.pgexecute ERROR - traceback: 'Traceback (most recent call last):\n  File "/usr/local/Cellar/pgcli/1.9.1/libexec/lib/python2.7/site-packages/pgcli/pgexecute.py", line 319, in run\n    yield self.execute_normal_sql(sql) + (sql, True)\n  File "/usr/local/Cellar/pgcli/1.9.1/libexec/lib/python2.7/site-packages/pgcli/pgexecute.py", line 355, in execute_normal_sql\n    cur.execute(split_sql)\nProgrammingError: column s.profile_type does not exist\nLINE 4:   sum(case when s.profile_type = 0 then 1 else 0 end) as bor...\n                        ^\n\n'
2018-08-01 12:19:04,821 (42523/MainThread) pgcli.main INFO - Default pager found in PAGER environment variable: "less"
2018-08-01 13:13:45,208 (42523/MainThread) pgcli.pgexecute ERROR - sql: u'select search_params from verification_address_verification_id3_search_results order by created_at desc limit 10', error: ProgrammingError('column "search_params" does not exist\nLINE 1: select search_params from verification_address_verification_...\n               ^\n',)
2018-08-01 13:13:45,239 (42523/MainThread) pgcli.pgexecute ERROR - traceback: 'Traceback (most recent call last):\n  File "/usr/local/Cellar/pgcli/1.9.1/libexec/lib/python2.7/site-packages/pgcli/pgexecute.py", line 319, in run\n    yield self.execute_normal_sql(sql) + (sql, True)\n  File "/usr/local/Cellar/pgcli/1.9.1/libexec/lib/python2.7/site-packages/pgcli/pgexecute.py", line 355, in execute_normal_sql\n    cur.execute(split_sql)\nProgrammingError: column "search_params" does not exist\nLINE 1: select search_params from verification_address_verification_...\n               ^\n\n'
2018-08-01 13:49:25,021 (42523/MainThread) pgcli.pgexecute ERROR - sql: u'', error: ProgrammingError("can't execute an empty query",)
2018-08-01 13:49:25,021 (42523/MainThread) pgcli.pgexecute ERROR - traceback: 'Traceback (most recent call last):\n  File "/usr/local/Cellar/pgcli/1.9.1/libexec/lib/python2.7/site-packages/pgcli/pgexecute.py", line 319, in run\n    yield self.execute_normal_sql(sql) + (sql, True)\n  File "/usr/local/Cellar/pgcli/1.9.1/libexec/lib/python2.7/site-packages/pgcli/pgexecute.py", line 355, in execute_normal_sql\n    cur.execute(split_sql)\nProgrammingError: can\'t execute an empty query\n'
2018-08-01 13:50:31,882 (42523/MainThread) pgcli.pgexecute ERROR - sql: u"SELECT\n  u.id AS user_id,\n  CONCAT_WS(' ', u.firstname, u.surname) AS name,\n  u.email,\n  u.created_at AS registration_date,\n  u.uuid AS user_uuid,\n  u.active AS user_active,\n  u.role > 0 AS user_administrator,\n  o.uuid AS owner_uuid,\n  o.hide AS hidden_owner_profile,\n  d.name AS dog_name,\n  d.uuid AS dog_uuid,\n  b.uuid AS borrower_uuid,\n  b.hide AS hidden_borrower_profile,\n  uc.marketing_permission,\n  s.id AS subscription_id,\n  s.id IS NOT NULL AS subscribed,\n  COALESCE(db.name, d.breed) AS dog_breed_name\nFROM\n  users u\n  INNER JOIN user_identities ui ON u.id = ui.user_id\n  INNER JOIN user_configurations uc ON u.id = uc.user_id\n  LEFT OUTER JOIN subscriptions s ON u.id = s.user_id AND s.state = 0\n  LEFT OUTER JOIN payments p ON u.id = p.user_id\n  LEFT OUTER JOIN borrowers b ON ui.id = b.user_identity_id AND b.deleted_at IS NULL\n  LEFT OUTER JOIN owners o ON ui.id = o.user_identity_id AND o.deleted_at IS NULL\n  LEFT OUTER JOIN dogs d ON o.id = d.owner_id AND d.active = TRUE\n  LEFT OUTER JOIN dog_breeds db ON db.id = d.dog_breed_id\n  LEFT OUTER JOIN verifications v ON v.user_id = u.id AND v.state = 0\n  LEFT OUTER JOIN verification_phone_verifications vpv ON v.id = vpv.verification_id\nWHERE LOWER(u.surname) LIKE '%dave%' OR LOWER(u.firstname) LIKE '%dave%')\nGROUP BY u.id, o.uuid, o.hide, d.name, d.uuid, b.uuid, b.hide, uc.marketing_permission, s.id, d.breed, db.name\nORDER BY u.created_at DESC\nLIMIT 25 OFFSET 25", error: ProgrammingError('syntax error at or near ")"\nLINE 31: ....surname) LIKE \'%dave%\' OR LOWER(u.firstname) LIKE \'%dave%\')\n                                                                       ^\n',)
2018-08-01 13:50:31,883 (42523/MainThread) pgcli.pgexecute ERROR - traceback: 'Traceback (most recent call last):\n  File "/usr/local/Cellar/pgcli/1.9.1/libexec/lib/python2.7/site-packages/pgcli/pgexecute.py", line 319, in run\n    yield self.execute_normal_sql(sql) + (sql, True)\n  File "/usr/local/Cellar/pgcli/1.9.1/libexec/lib/python2.7/site-packages/pgcli/pgexecute.py", line 355, in execute_normal_sql\n    cur.execute(split_sql)\nProgrammingError: syntax error at or near ")"\nLINE 31: ....surname) LIKE \'%dave%\' OR LOWER(u.firstname) LIKE \'%dave%\')\n                                                                       ^\n\n'
2018-08-01 13:59:37,958 (42523/MainThread) pgcli.pgexecute ERROR - sql: u"select u.id, u.firstname, u.surname from users u where u.firstname similar to '(dave|burn)' or u.lastname similar to '(dave|burn)'", error: ProgrammingError("column u.lastname does not exist\nLINE 1: ...s u where u.firstname similar to '(dave|burn)' or u.lastname...\n                                                             ^\n",)
2018-08-01 13:59:37,959 (42523/MainThread) pgcli.pgexecute ERROR - traceback: 'Traceback (most recent call last):\n  File "/usr/local/Cellar/pgcli/1.9.1/libexec/lib/python2.7/site-packages/pgcli/pgexecute.py", line 319, in run\n    yield self.execute_normal_sql(sql) + (sql, True)\n  File "/usr/local/Cellar/pgcli/1.9.1/libexec/lib/python2.7/site-packages/pgcli/pgexecute.py", line 355, in execute_normal_sql\n    cur.execute(split_sql)\nProgrammingError: column u.lastname does not exist\nLINE 1: ...s u where u.firstname similar to \'(dave|burn)\' or u.lastname...\n                                                             ^\n\n'
2018-08-01 14:03:45,205 (42523/MainThread) pgcli.pgexecute ERROR - sql: u"select u.id, u.firstname, u.surname from users u where u.firstname ~* '(dave|burn)' or u.surname ~* '(dave|burn)' order by levenshtein(u.firstname || ' ' || u.surname, 'dave burn') limit 20", error: ProgrammingError("function levenshtein(text, unknown) does not exist\nLINE 1: ...ave|burn)' or u.surname ~* '(dave|burn)' order by levenshtei...\n                                                             ^\nHINT:  No function matches the given name and argument types. You might need to add explicit type casts.\n",)
2018-08-01 14:03:45,206 (42523/MainThread) pgcli.pgexecute ERROR - traceback: 'Traceback (most recent call last):\n  File "/usr/local/Cellar/pgcli/1.9.1/libexec/lib/python2.7/site-packages/pgcli/pgexecute.py", line 319, in run\n    yield self.execute_normal_sql(sql) + (sql, True)\n  File "/usr/local/Cellar/pgcli/1.9.1/libexec/lib/python2.7/site-packages/pgcli/pgexecute.py", line 355, in execute_normal_sql\n    cur.execute(split_sql)\nProgrammingError: function levenshtein(text, unknown) does not exist\nLINE 1: ...ave|burn)\' or u.surname ~* \'(dave|burn)\' order by levenshtei...\n                                                             ^\nHINT:  No function matches the given name and argument types. You might need to add explicit type casts.\n\n'
2018-08-01 14:04:42,084 (42523/MainThread) pgcli.pgexecute ERROR - sql: u"select u.id, u.firstname, u.surname, levenshtein(u.firstname || ' ' || u.surname, 'dave burn') from users u where u.firstname ~* '(dave|burn)' or u.surname ~* '(dave|burn)' limit 20", error: ProgrammingError('function levenshtein(text, unknown) does not exist\nLINE 1: select u.id, u.firstname, u.surname, levenshtein(u.firstname...\n                                             ^\nHINT:  No function matches the given name and argument types. You might need to add explicit type casts.\n',)
2018-08-01 14:04:42,085 (42523/MainThread) pgcli.pgexecute ERROR - traceback: 'Traceback (most recent call last):\n  File "/usr/local/Cellar/pgcli/1.9.1/libexec/lib/python2.7/site-packages/pgcli/pgexecute.py", line 319, in run\n    yield self.execute_normal_sql(sql) + (sql, True)\n  File "/usr/local/Cellar/pgcli/1.9.1/libexec/lib/python2.7/site-packages/pgcli/pgexecute.py", line 355, in execute_normal_sql\n    cur.execute(split_sql)\nProgrammingError: function levenshtein(text, unknown) does not exist\nLINE 1: select u.id, u.firstname, u.surname, levenshtein(u.firstname...\n                                             ^\nHINT:  No function matches the given name and argument types. You might need to add explicit type casts.\n\n'
2018-08-01 14:17:54,941 (42523/MainThread) pgcli.pgexecute ERROR - sql: u'clear', error: ProgrammingError('syntax error at or near "clear"\nLINE 1: clear\n        ^\n',)
2018-08-01 14:17:54,942 (42523/MainThread) pgcli.pgexecute ERROR - traceback: 'Traceback (most recent call last):\n  File "/usr/local/Cellar/pgcli/1.9.1/libexec/lib/python2.7/site-packages/pgcli/pgexecute.py", line 319, in run\n    yield self.execute_normal_sql(sql) + (sql, True)\n  File "/usr/local/Cellar/pgcli/1.9.1/libexec/lib/python2.7/site-packages/pgcli/pgexecute.py", line 355, in execute_normal_sql\n    cur.execute(split_sql)\nProgrammingError: syntax error at or near "clear"\nLINE 1: clear\n        ^\n\n'
2018-08-02 10:31:12,190 (42523/MainThread) pgcli.pgexecute ERROR - sql: u'select * from user_iden', error: ProgrammingError('relation "user_iden" does not exist\nLINE 1: select * from user_iden\n                      ^\n',)
2018-08-02 10:31:12,192 (42523/MainThread) pgcli.pgexecute ERROR - traceback: 'Traceback (most recent call last):\n  File "/usr/local/Cellar/pgcli/1.9.1/libexec/lib/python2.7/site-packages/pgcli/pgexecute.py", line 319, in run\n    yield self.execute_normal_sql(sql) + (sql, True)\n  File "/usr/local/Cellar/pgcli/1.9.1/libexec/lib/python2.7/site-packages/pgcli/pgexecute.py", line 355, in execute_normal_sql\n    cur.execute(split_sql)\nProgrammingError: relation "user_iden" does not exist\nLINE 1: select * from user_iden\n                      ^\n\n'
2018-08-02 14:00:52,125 (42523/MainThread) pgcli.pgexecute ERROR - sql: u'select min(3, 4)', error: ProgrammingError('function min(integer, integer) does not exist\nLINE 1: select min(3, 4)\n               ^\nHINT:  No function matches the given name and argument types. You might need to add explicit type casts.\n',)
2018-08-02 14:00:52,126 (42523/MainThread) pgcli.pgexecute ERROR - traceback: 'Traceback (most recent call last):\n  File "/usr/local/Cellar/pgcli/1.9.1/libexec/lib/python2.7/site-packages/pgcli/pgexecute.py", line 319, in run\n    yield self.execute_normal_sql(sql) + (sql, True)\n  File "/usr/local/Cellar/pgcli/1.9.1/libexec/lib/python2.7/site-packages/pgcli/pgexecute.py", line 355, in execute_normal_sql\n    cur.execute(split_sql)\nProgrammingError: function min(integer, integer) does not exist\nLINE 1: select min(3, 4)\n               ^\nHINT:  No function matches the given name and argument types. You might need to add explicit type casts.\n\n'
2018-08-03 13:49:06,709 (42523/MainThread) pgcli.pgexecute ERROR - sql: u"select date'2018-08-04' = date()", error: ProgrammingError("function date() does not exist\nLINE 1: select date'2018-08-04' = date()\n                                  ^\nHINT:  No function matches the given name and argument types. You might need to add explicit type casts.\n",)
2018-08-03 13:49:06,710 (42523/MainThread) pgcli.pgexecute ERROR - traceback: 'Traceback (most recent call last):\n  File "/usr/local/Cellar/pgcli/1.9.1/libexec/lib/python2.7/site-packages/pgcli/pgexecute.py", line 319, in run\n    yield self.execute_normal_sql(sql) + (sql, True)\n  File "/usr/local/Cellar/pgcli/1.9.1/libexec/lib/python2.7/site-packages/pgcli/pgexecute.py", line 355, in execute_normal_sql\n    cur.execute(split_sql)\nProgrammingError: function date() does not exist\nLINE 1: select date\'2018-08-04\' = date()\n                                  ^\nHINT:  No function matches the given name and argument types. You might need to add explicit type casts.\n\n'
2018-08-03 13:49:15,506 (42523/MainThread) pgcli.pgexecute ERROR - sql: u"select date'2018-08-04' = today()", error: ProgrammingError("function today() does not exist\nLINE 1: select date'2018-08-04' = today()\n                                  ^\nHINT:  No function matches the given name and argument types. You might need to add explicit type casts.\n",)
2018-08-03 13:49:15,506 (42523/MainThread) pgcli.pgexecute ERROR - traceback: 'Traceback (most recent call last):\n  File "/usr/local/Cellar/pgcli/1.9.1/libexec/lib/python2.7/site-packages/pgcli/pgexecute.py", line 319, in run\n    yield self.execute_normal_sql(sql) + (sql, True)\n  File "/usr/local/Cellar/pgcli/1.9.1/libexec/lib/python2.7/site-packages/pgcli/pgexecute.py", line 355, in execute_normal_sql\n    cur.execute(split_sql)\nProgrammingError: function today() does not exist\nLINE 1: select date\'2018-08-04\' = today()\n                                  ^\nHINT:  No function matches the given name and argument types. You might need to add explicit type casts.\n\n'
2018-08-03 14:30:52,019 (42523/MainThread) pgcli.pgexecute ERROR - sql: u'select * from subscriptions where user_id =', error: ProgrammingError('syntax error at end of input\nLINE 1: select * from subscriptions where user_id =\n                                                   ^\n',)
2018-08-03 14:30:52,020 (42523/MainThread) pgcli.pgexecute ERROR - traceback: 'Traceback (most recent call last):\n  File "/usr/local/Cellar/pgcli/1.9.1/libexec/lib/python2.7/site-packages/pgcli/pgexecute.py", line 319, in run\n    yield self.execute_normal_sql(sql) + (sql, True)\n  File "/usr/local/Cellar/pgcli/1.9.1/libexec/lib/python2.7/site-packages/pgcli/pgexecute.py", line 355, in execute_normal_sql\n    cur.execute(split_sql)\nProgrammingError: syntax error at end of input\nLINE 1: select * from subscriptions where user_id =\n                                                   ^\n\n'
2018-08-08 15:29:14,624 (25373/MainThread) pgcli.main INFO - Default pager found in PAGER environment variable: "less"
2018-08-08 17:12:17,401 (28137/MainThread) pgcli.main INFO - Default pager found in PAGER environment variable: "less"
2018-08-08 17:24:09,495 (28137/MainThread) pgcli.pgexecute ERROR - sql: u"SELECT\n  u.created_at::date AS reg_date,\n  COUNT(s.id) AS total_subscription_count,\n  sum(case when sp.profile_type = 0 then 1 else 0 end) as borrower_count,\n  sum(case when sp.profile_type = 1 then 1 else 0 end) as owner_count\nFROM\n  users u\n  INNER JOIN subscriptions s ON u.created_at::date BETWEEN s.created_at::date AND s.current_period_ends_at::date\n  INNER JOIN subscription_plans sp ON s.subscription_plan_id = sp.id\nWHERE u.created_at < '2018-01-01' AND u.created_at > '2017-12-20'\nLIMIT 10", error: ProgrammingError('column "u.created_at" must appear in the GROUP BY clause or be used in an aggregate function\nLINE 2:   u.created_at::date AS reg_date,\n          ^\n',)
2018-08-08 17:24:09,497 (28137/MainThread) pgcli.pgexecute ERROR - traceback: 'Traceback (most recent call last):\n  File "/usr/local/Cellar/pgcli/1.9.1/libexec/lib/python2.7/site-packages/pgcli/pgexecute.py", line 319, in run\n    yield self.execute_normal_sql(sql) + (sql, True)\n  File "/usr/local/Cellar/pgcli/1.9.1/libexec/lib/python2.7/site-packages/pgcli/pgexecute.py", line 355, in execute_normal_sql\n    cur.execute(split_sql)\nProgrammingError: column "u.created_at" must appear in the GROUP BY clause or be used in an aggregate function\nLINE 2:   u.created_at::date AS reg_date,\n          ^\n\n'
2018-08-08 17:25:52,253 (28137/MainThread) pgcli.pgexecute ERROR - sql: u"SELECT\n  u.created_at::date AS reg_date,\n  COUNT(s.id) AS total_subscription_count,\n  sum(case when sp.profile_type = 0 then 1 else 0 end) as borrower_count,\n  sum(case when sp.profile_type = 1 then 1 else 0 end) as owner_count\nFROM\n  users u\n  INNER JOIN subscriptions s ON u.created_at::date BETWEEN s.created_at::date AND s.current_period_ends_at::date\n  INNER JOIN subscription_plans sp ON s.subscription_plan_id = sp.id\nWHERE u.created_at::date < '2018-01-01' AND u.created_at::date > '2017-12-20'\nGROUP BY u.created_at::date\nLIMIT 10", error: QueryCanceledError('canceling statement due to user request\n',)
2018-08-08 17:25:52,253 (28137/MainThread) pgcli.pgexecute ERROR - traceback: 'Traceback (most recent call last):\n  File "/usr/local/Cellar/pgcli/1.9.1/libexec/lib/python2.7/site-packages/pgcli/pgexecute.py", line 319, in run\n    yield self.execute_normal_sql(sql) + (sql, True)\n  File "/usr/local/Cellar/pgcli/1.9.1/libexec/lib/python2.7/site-packages/pgcli/pgexecute.py", line 355, in execute_normal_sql\n    cur.execute(split_sql)\nQueryCanceledError: canceling statement due to user request\n\n'
2018-08-08 17:25:52,253 (28137/MainThread) pgcli.main ERROR - sql: u"SELECT\n  u.created_at::date AS reg_date,\n  COUNT(s.id) AS total_subscription_count,\n  sum(case when sp.profile_type = 0 then 1 else 0 end) as borrower_count,\n  sum(case when sp.profile_type = 1 then 1 else 0 end) as owner_count\nFROM\n  users u\n  INNER JOIN subscriptions s ON u.created_at::date BETWEEN s.created_at::date AND s.current_period_ends_at::date\n  INNER JOIN subscription_plans sp ON s.subscription_plan_id = sp.id\nWHERE u.created_at::date < '2018-01-01' AND u.created_at::date > '2017-12-20'\nGROUP BY u.created_at::date\nLIMIT 10;", error: QueryCanceledError('canceling statement due to user request\n',)
2018-08-08 17:25:52,255 (28137/MainThread) pgcli.main ERROR - traceback: 'Traceback (most recent call last):\n  File "/usr/local/Cellar/pgcli/1.9.1/libexec/lib/python2.7/site-packages/pgcli/main.py", line 462, in execute_command\n    output, query = self._evaluate_command(text)\n  File "/usr/local/Cellar/pgcli/1.9.1/libexec/lib/python2.7/site-packages/pgcli/main.py", line 685, in _evaluate_command\n    for title, cur, headers, status, sql, success in res:\n  File "/usr/local/Cellar/pgcli/1.9.1/libexec/lib/python2.7/site-packages/pgcli/pgexecute.py", line 319, in run\n    yield self.execute_normal_sql(sql) + (sql, True)\n  File "/usr/local/Cellar/pgcli/1.9.1/libexec/lib/python2.7/site-packages/pgcli/pgexecute.py", line 355, in execute_normal_sql\n    cur.execute(split_sql)\nQueryCanceledError: canceling statement due to user request\n\n'
2018-08-09 10:03:46,354 (28137/MainThread) pgcli.pgexecute ERROR - sql: u"SELECT\n  COUNT(s.id) AS total_subscription_count,\n  sum(case when sp.profile_type = 0 then 1 else 0 end) as borrower_count,\n  sum(case when sp.profile_type = 1 then 1 else 0 end) as owner_count\nFROM\n  subscriptions s\n  INNER JOIN subscription_plans sp ON s.subscription_plan_id = sp.id\nWHERE s.created_at < datetime'2018-07-31T23:59:59'\nAND s.current_period_ends_at > datetime'2018-07-01T00:00:00'\nLIMIT 10", error: ProgrammingError('type "datetime" does not exist\nLINE 8: WHERE s.created_at < datetime\'2018-07-31T23:59:59\'\n                             ^\n',)
2018-08-09 10:03:46,356 (28137/MainThread) pgcli.pgexecute ERROR - traceback: 'Traceback (most recent call last):\n  File "/usr/local/Cellar/pgcli/1.9.1/libexec/lib/python2.7/site-packages/pgcli/pgexecute.py", line 319, in run\n    yield self.execute_normal_sql(sql) + (sql, True)\n  File "/usr/local/Cellar/pgcli/1.9.1/libexec/lib/python2.7/site-packages/pgcli/pgexecute.py", line 355, in execute_normal_sql\n    cur.execute(split_sql)\nProgrammingError: type "datetime" does not exist\nLINE 8: WHERE s.created_at < datetime\'2018-07-31T23:59:59\'\n                             ^\n\n'
2018-08-09 10:17:11,372 (28137/MainThread) pgcli.pgexecute ERROR - sql: u"SELECT\n  ms.month_start AS month_start,\n  ms.month_start + interval'1 month' - interval'1 second' AS month_end,\n  COUNT(s.id) AS total_subscription_count,\n  sum(case when sp.profile_type = 0 then 1 else 0 end) as borrower_count,\n  sum(case when sp.profile_type = 1 then 1 else 0 end) as owner_count\nFROM\n  generate_series(timestamp'2017-01-01', timestamp'2017-12-01', interval'1 month') AS ms(month_start)\nINNER JOIN subscriptions s ON s.created_at < (ms.month_start + interval'1 month' - interval'1 second') AND s.current_period_ends_at > ms.month_start\nINNER JOIN subscription_plans sp ON s.subscription_plan_id = sp.id\nLIMIT 12", error: ProgrammingError('column "ms.month_start" must appear in the GROUP BY clause or be used in an aggregate function\nLINE 2:   ms.month_start AS month_start,\n          ^\n',)
2018-08-09 10:17:11,372 (28137/MainThread) pgcli.pgexecute ERROR - traceback: 'Traceback (most recent call last):\n  File "/usr/local/Cellar/pgcli/1.9.1/libexec/lib/python2.7/site-packages/pgcli/pgexecute.py", line 319, in run\n    yield self.execute_normal_sql(sql) + (sql, True)\n  File "/usr/local/Cellar/pgcli/1.9.1/libexec/lib/python2.7/site-packages/pgcli/pgexecute.py", line 355, in execute_normal_sql\n    cur.execute(split_sql)\nProgrammingError: column "ms.month_start" must appear in the GROUP BY clause or be used in an aggregate function\nLINE 2:   ms.month_start AS month_start,\n          ^\n\n'
2018-08-09 10:40:08,014 (28137/MainThread) pgcli.pgexecute ERROR - sql: u"select timestamp'2018-07-15T12:34:00' && daterange('2018-07-01', '2018-08-01', '[)')", error: ProgrammingError("operator does not exist: timestamp without time zone && daterange\nLINE 1: select timestamp'2018-07-15T12:34:00' && daterange('2018-07-...\n                                              ^\nHINT:  No operator matches the given name and argument type(s). You might need to add explicit type casts.\n",)
2018-08-09 10:40:08,015 (28137/MainThread) pgcli.pgexecute ERROR - traceback: 'Traceback (most recent call last):\n  File "/usr/local/Cellar/pgcli/1.9.1/libexec/lib/python2.7/site-packages/pgcli/pgexecute.py", line 319, in run\n    yield self.execute_normal_sql(sql) + (sql, True)\n  File "/usr/local/Cellar/pgcli/1.9.1/libexec/lib/python2.7/site-packages/pgcli/pgexecute.py", line 355, in execute_normal_sql\n    cur.execute(split_sql)\nProgrammingError: operator does not exist: timestamp without time zone && daterange\nLINE 1: select timestamp\'2018-07-15T12:34:00\' && daterange(\'2018-07-...\n                                              ^\nHINT:  No operator matches the given name and argument type(s). You might need to add explicit type casts.\n\n'
2018-08-09 10:43:32,213 (28137/MainThread) pgcli.pgexecute ERROR - sql: u"SELECT\n  daterange(ms.month_start, ms.month_start + interval'1 month', '[)') AS month_range,\n  ms.month_start AS month_start,\n  ms.month_start + interval'1 month' - interval'1 second' AS month_end,\n  COUNT(s.id) AS total_subscription_count,\n  SUM(1 - sp.profile_type) AS borrower_count,\n  SUM(sp.profile_type) AS owner_count\nFROM\n  generate_series(timestamp'2017-01-01', timestamp'2017-12-01', interval'1 month') AS ms(month_start)\nINNER JOIN subscriptions s ON daterange(s.created_at, s.current_period_ends_at, '[]') && daterange(ms.month_start, ms.month_start + interval'1 month', '[)')\nINNER JOIN subscription_plans sp ON s.subscription_plan_id = sp.id\nGROUP BY ms.month_start\nORDER BY ms.month_start", error: ProgrammingError('function daterange(timestamp without time zone, timestamp without time zone, unknown) does not exist\nLINE 10: INNER JOIN subscriptions s ON daterange(s.created_at, s.curr...\n                                       ^\nHINT:  No function matches the given name and argument types. You might need to add explicit type casts.\n',)
2018-08-09 10:43:32,222 (28137/MainThread) pgcli.pgexecute ERROR - traceback: 'Traceback (most recent call last):\n  File "/usr/local/Cellar/pgcli/1.9.1/libexec/lib/python2.7/site-packages/pgcli/pgexecute.py", line 319, in run\n    yield self.execute_normal_sql(sql) + (sql, True)\n  File "/usr/local/Cellar/pgcli/1.9.1/libexec/lib/python2.7/site-packages/pgcli/pgexecute.py", line 355, in execute_normal_sql\n    cur.execute(split_sql)\nProgrammingError: function daterange(timestamp without time zone, timestamp without time zone, unknown) does not exist\nLINE 10: INNER JOIN subscriptions s ON daterange(s.created_at, s.curr...\n                                       ^\nHINT:  No function matches the given name and argument types. You might need to add explicit type casts.\n\n'
2018-08-09 10:44:18,805 (28137/MainThread) pgcli.pgexecute ERROR - sql: u"SELECT\n  daterange(ms.month_start, ms.month_start + interval'1 month', '[)') AS month_range,\n  ms.month_start AS month_start,\n  ms.month_start + interval'1 month' - interval'1 second' AS month_end,\n  COUNT(s.id) AS total_subscription_count,\n  SUM(1 - sp.profile_type) AS borrower_count,\n  SUM(sp.profile_type) AS owner_count\nFROM\n  generate_series(timestamp'2017-01-01', timestamp'2017-12-01', interval'1 month') AS ms(month_start)\nINNER JOIN subscriptions s ON tsrange(s.created_at, s.current_period_ends_at, '[]') && daterange(ms.month_start, ms.month_start + interval'1 month', '[)')\nINNER JOIN subscription_plans sp ON s.subscription_plan_id = sp.id\nGROUP BY ms.month_start\nORDER BY ms.month_start", error: ProgrammingError("function daterange(timestamp without time zone, timestamp without time zone, unknown) does not exist\nLINE 10: ...(s.created_at, s.current_period_ends_at, '[]') && daterange(...\n                                                              ^\nHINT:  No function matches the given name and argument types. You might need to add explicit type casts.\n",)
2018-08-09 10:44:18,825 (28137/MainThread) pgcli.pgexecute ERROR - traceback: 'Traceback (most recent call last):\n  File "/usr/local/Cellar/pgcli/1.9.1/libexec/lib/python2.7/site-packages/pgcli/pgexecute.py", line 319, in run\n    yield self.execute_normal_sql(sql) + (sql, True)\n  File "/usr/local/Cellar/pgcli/1.9.1/libexec/lib/python2.7/site-packages/pgcli/pgexecute.py", line 355, in execute_normal_sql\n    cur.execute(split_sql)\nProgrammingError: function daterange(timestamp without time zone, timestamp without time zone, unknown) does not exist\nLINE 10: ...(s.created_at, s.current_period_ends_at, \'[]\') && daterange(...\n                                                              ^\nHINT:  No function matches the given name and argument types. You might need to add explicit type casts.\n\n'
2018-08-09 10:44:54,396 (28137/MainThread) pgcli.pgexecute ERROR - sql: u"SELECT\n  daterange(ms.month_start, ms.month_start + interval'1 month', '[)') AS month_range,\n  ms.month_start AS month_start,\n  ms.month_start + interval'1 month' - interval'1 second' AS month_end,\n  COUNT(s.id) AS total_subscription_count,\n  SUM(1 - sp.profile_type) AS borrower_count,\n  SUM(sp.profile_type) AS owner_count\nFROM\n  generate_series(date'2017-01-01', date'2017-12-01', interval'1 month') AS ms(month_start)\nINNER JOIN subscriptions s ON tsrange(s.created_at, s.current_period_ends_at, '[]') && daterange(ms.month_start, ms.month_start + interval'1 month', '[)')\nINNER JOIN subscription_plans sp ON s.subscription_plan_id = sp.id\nGROUP BY ms.month_start\nORDER BY ms.month_start", error: ProgrammingError("function daterange(timestamp with time zone, timestamp with time zone, unknown) does not exist\nLINE 10: ...(s.created_at, s.current_period_ends_at, '[]') && daterange(...\n                                                              ^\nHINT:  No function matches the given name and argument types. You might need to add explicit type casts.\n",)
2018-08-09 10:44:54,406 (28137/MainThread) pgcli.pgexecute ERROR - traceback: 'Traceback (most recent call last):\n  File "/usr/local/Cellar/pgcli/1.9.1/libexec/lib/python2.7/site-packages/pgcli/pgexecute.py", line 319, in run\n    yield self.execute_normal_sql(sql) + (sql, True)\n  File "/usr/local/Cellar/pgcli/1.9.1/libexec/lib/python2.7/site-packages/pgcli/pgexecute.py", line 355, in execute_normal_sql\n    cur.execute(split_sql)\nProgrammingError: function daterange(timestamp with time zone, timestamp with time zone, unknown) does not exist\nLINE 10: ...(s.created_at, s.current_period_ends_at, \'[]\') && daterange(...\n                                                              ^\nHINT:  No function matches the given name and argument types. You might need to add explicit type casts.\n\n'
2018-08-09 10:45:48,408 (28137/MainThread) pgcli.pgexecute ERROR - sql: u"SELECT\n  tsrange(ms.month_start, ms.month_start + interval'1 month', '[)') AS month_range,\n  ms.month_start AS month_start,\n  ms.month_start + interval'1 month' - interval'1 second' AS month_end,\n  COUNT(s.id) AS total_subscription_count,\n  SUM(1 - sp.profile_type) AS borrower_count,\n  SUM(sp.profile_type) AS owner_count\nFROM\n  generate_series(timestamp'2017-01-01', timestamp'2017-12-01', interval'1 month') AS ms(month_start)\nINNER JOIN subscriptions s ON tsrange(s.created_at, s.current_period_ends_at, '[]') && daterange(ms.month_start, ms.month_start + interval'1 month', '[)')\nINNER JOIN subscription_plans sp ON s.subscription_plan_id = sp.id\nGROUP BY ms.month_start\nORDER BY ms.month_start", error: ProgrammingError("function daterange(timestamp without time zone, timestamp without time zone, unknown) does not exist\nLINE 10: ...(s.created_at, s.current_period_ends_at, '[]') && daterange(...\n                                                              ^\nHINT:  No function matches the given name and argument types. You might need to add explicit type casts.\n",)
2018-08-09 10:45:48,409 (28137/MainThread) pgcli.pgexecute ERROR - traceback: 'Traceback (most recent call last):\n  File "/usr/local/Cellar/pgcli/1.9.1/libexec/lib/python2.7/site-packages/pgcli/pgexecute.py", line 319, in run\n    yield self.execute_normal_sql(sql) + (sql, True)\n  File "/usr/local/Cellar/pgcli/1.9.1/libexec/lib/python2.7/site-packages/pgcli/pgexecute.py", line 355, in execute_normal_sql\n    cur.execute(split_sql)\nProgrammingError: function daterange(timestamp without time zone, timestamp without time zone, unknown) does not exist\nLINE 10: ...(s.created_at, s.current_period_ends_at, \'[]\') && daterange(...\n                                                              ^\nHINT:  No function matches the given name and argument types. You might need to add explicit type casts.\n\n'
2018-08-09 11:06:59,850 (28137/MainThread) pgcli.pgexecute ERROR - sql: u"SELECT\n  ms.month_start AS month_start,\n  ms.month_start + interval'1 month' AS month_end,\n  COUNT(u.id) AS total_user_count\nFROM\n  generate_series(timestamp'2012-07-01', timestamp'2018-08-01', interval'1 month') AS ms(month_start)\nINNER JOIN users u ON u.created_at < ms.month_start + interval'1 month')\nGROUP BY ms.month_start\nORDER BY ms.month_start", error: ProgrammingError('syntax error at or near ")"\nLINE 7: ...sers u ON u.created_at < ms.month_start + interval\'1 month\')\n                                                                      ^\n',)
2018-08-09 11:06:59,855 (28137/MainThread) pgcli.pgexecute ERROR - traceback: 'Traceback (most recent call last):\n  File "/usr/local/Cellar/pgcli/1.9.1/libexec/lib/python2.7/site-packages/pgcli/pgexecute.py", line 319, in run\n    yield self.execute_normal_sql(sql) + (sql, True)\n  File "/usr/local/Cellar/pgcli/1.9.1/libexec/lib/python2.7/site-packages/pgcli/pgexecute.py", line 355, in execute_normal_sql\n    cur.execute(split_sql)\nProgrammingError: syntax error at or near ")"\nLINE 7: ...sers u ON u.created_at < ms.month_start + interval\'1 month\')\n                                                                      ^\n\n'
2018-08-21 15:07:50,489 (40158/MainThread) pgcli.main INFO - Default pager found in PAGER environment variable: "less"
2018-08-21 16:19:33,639 (43464/MainThread) pgcli.main INFO - Default pager found in PAGER environment variable: "less"
2018-08-21 16:39:49,551 (43464/MainThread) pgcli.pgexecute ERROR - sql: u"select u.id, u.firstname, u.surname, count(dt.token)\nfrom users u\ninner join user_authentication_providers uap on u.id = uap.user_id and uap.facebook_uid is not null\nleft outer join device_tokens dt on u.id = dt.user_id\ngroup by u.id, u.firstname, u.surname\nwhere u.created_at > '2018-08-21T13:35:00'\nlimit 100", error: ProgrammingError('syntax error at or near "where"\nLINE 6: where u.created_at > \'2018-08-21T13:35:00\'\n        ^\n',)
2018-08-21 16:39:49,553 (43464/MainThread) pgcli.pgexecute ERROR - traceback: 'Traceback (most recent call last):\n  File "/usr/local/Cellar/pgcli/1.9.1/libexec/lib/python2.7/site-packages/pgcli/pgexecute.py", line 319, in run\n    yield self.execute_normal_sql(sql) + (sql, True)\n  File "/usr/local/Cellar/pgcli/1.9.1/libexec/lib/python2.7/site-packages/pgcli/pgexecute.py", line 355, in execute_normal_sql\n    cur.execute(split_sql)\nProgrammingError: syntax error at or near "where"\nLINE 6: where u.created_at > \'2018-08-21T13:35:00\'\n        ^\n\n'
2018-08-22 09:47:54,381 (48543/MainThread) pgcli.main INFO - Default pager found in PAGER environment variable: "less"
2018-08-22 10:20:22,186 (50021/MainThread) pgcli.main INFO - Default pager found in PAGER environment variable: "less"
2018-08-23 13:23:04,560 (29715/MainThread) pgcli.main INFO - Default pager found in PAGER environment variable: "less"
2018-08-23 13:58:04,014 (29715/MainThread) pgcli.pgexecute ERROR - sql: u'select u.id, u.uuid, u.email, max(s.current_period_ends_at), v.state from users u inner join subscriptions s on u.id = s.user_id inner join verifications v on u.id = v.user_id where v.state = 0 and u.deleted_at is null group by u.id, u.uuid, u.email, v.state having max(s.current_period_ends_at) < now() order by max(s.current_period_ends_at desc) limit 100', error: ProgrammingError('syntax error at or near "desc"\nLINE 1: ...at) < now() order by max(s.current_period_ends_at desc) limi...\n                                                             ^\n',)
2018-08-23 13:58:04,016 (29715/MainThread) pgcli.pgexecute ERROR - traceback: 'Traceback (most recent call last):\n  File "/usr/local/Cellar/pgcli/1.9.1/libexec/lib/python2.7/site-packages/pgcli/pgexecute.py", line 319, in run\n    yield self.execute_normal_sql(sql) + (sql, True)\n  File "/usr/local/Cellar/pgcli/1.9.1/libexec/lib/python2.7/site-packages/pgcli/pgexecute.py", line 355, in execute_normal_sql\n    cur.execute(split_sql)\nProgrammingError: syntax error at or near "desc"\nLINE 1: ...at) < now() order by max(s.current_period_ends_at desc) limi...\n                                                             ^\n\n'
2018-08-23 14:07:18,865 (29715/MainThread) pgcli.pgexecute ERROR - sql: u'u.active', error: ProgrammingError('syntax error at or near "u"\nLINE 1: u.active\n        ^\n',)
2018-08-23 14:07:18,866 (29715/MainThread) pgcli.pgexecute ERROR - traceback: 'Traceback (most recent call last):\n  File "/usr/local/Cellar/pgcli/1.9.1/libexec/lib/python2.7/site-packages/pgcli/pgexecute.py", line 319, in run\n    yield self.execute_normal_sql(sql) + (sql, True)\n  File "/usr/local/Cellar/pgcli/1.9.1/libexec/lib/python2.7/site-packages/pgcli/pgexecute.py", line 355, in execute_normal_sql\n    cur.execute(split_sql)\nProgrammingError: syntax error at or near "u"\nLINE 1: u.active\n        ^\n\n'
2018-08-23 15:01:33,934 (32971/MainThread) pgcli.main INFO - Default pager found in PAGER environment variable: "less"
2018-08-23 15:03:05,943 (32971/MainThread) pgcli.pgexecute ERROR - sql: u'select count(1) from subscriptions where state = 0 and current_period_ends_at < today()', error: ProgrammingError('function today() does not exist\nLINE 1: ...iptions where state = 0 and current_period_ends_at < today()\n                                                                ^\nHINT:  No function matches the given name and argument types. You might need to add explicit type casts.\n',)
2018-08-23 15:03:05,946 (32971/MainThread) pgcli.pgexecute ERROR - traceback: 'Traceback (most recent call last):\n  File "/usr/local/Cellar/pgcli/1.9.1/libexec/lib/python2.7/site-packages/pgcli/pgexecute.py", line 319, in run\n    yield self.execute_normal_sql(sql) + (sql, True)\n  File "/usr/local/Cellar/pgcli/1.9.1/libexec/lib/python2.7/site-packages/pgcli/pgexecute.py", line 355, in execute_normal_sql\n    cur.execute(split_sql)\nProgrammingError: function today() does not exist\nLINE 1: ...iptions where state = 0 and current_period_ends_at < today()\n                                                                ^\nHINT:  No function matches the given name and argument types. You might need to add explicit type casts.\n\n'
2018-08-23 15:06:20,098 (32971/MainThread) pgcli.pgexecute ERROR - sql: u'select u.uuid, u.email, s.user_id, s.auto_renew, s.current_period_ends_at, v.state as verification_state, vav.verified as address_verified, vpv.verified as phone_verified, rbr.type, rbr.customer_id\nfrom subscriptions s\ninner join recurring_billing_resources rbr on s.id = rbr.subscription_id\ninner join users u on s.user_id = u.id\ninner join verifications v on u.id = v.user_id\nleft outer join verification_address_verifications vav on v.id = vav.verification_id\nleft outer join verification_phone_verifications vpv on v.id = vpv.verification_id\nwhere s.state = 2\norder by s.current_period_ends_at desc', error: ProgrammingError('column rbr.customer_id does not exist\nLINE 1: ...rified, vpv.verified as phone_verified, rbr.type, rbr.custom...\n                                                             ^\n',)
2018-08-23 15:06:20,099 (32971/MainThread) pgcli.pgexecute ERROR - traceback: 'Traceback (most recent call last):\n  File "/usr/local/Cellar/pgcli/1.9.1/libexec/lib/python2.7/site-packages/pgcli/pgexecute.py", line 319, in run\n    yield self.execute_normal_sql(sql) + (sql, True)\n  File "/usr/local/Cellar/pgcli/1.9.1/libexec/lib/python2.7/site-packages/pgcli/pgexecute.py", line 355, in execute_normal_sql\n    cur.execute(split_sql)\nProgrammingError: column rbr.customer_id does not exist\nLINE 1: ...rified, vpv.verified as phone_verified, rbr.type, rbr.custom...\n                                                             ^\n\n'
2018-08-24 09:58:16,310 (53959/MainThread) pgcli.main INFO - Default pager found in PAGER environment variable: "less"
2018-08-24 12:44:01,828 (53959/MainThread) pgcli.pgexecute ERROR - sql: u'select * from subscription_re', error: ProgrammingError('relation "subscription_re" does not exist\nLINE 1: select * from subscription_re\n                      ^\n',)
2018-08-24 12:44:01,831 (53959/MainThread) pgcli.pgexecute ERROR - traceback: 'Traceback (most recent call last):\n  File "/usr/local/Cellar/pgcli/1.9.1/libexec/lib/python2.7/site-packages/pgcli/pgexecute.py", line 319, in run\n    yield self.execute_normal_sql(sql) + (sql, True)\n  File "/usr/local/Cellar/pgcli/1.9.1/libexec/lib/python2.7/site-packages/pgcli/pgexecute.py", line 355, in execute_normal_sql\n    cur.execute(split_sql)\nProgrammingError: relation "subscription_re" does not exist\nLINE 1: select * from subscription_re\n                      ^\n\n'
2018-08-28 09:52:37,978 (1617/MainThread) pgcli.main INFO - Default pager found in PAGER environment variable: "less"
2018-08-29 09:22:00,065 (16046/MainThread) pgcli.main INFO - Default pager found in PAGER environment variable: "less"
2018-08-29 10:13:06,554 (17627/MainThread) pgcli.main INFO - Default pager found in PAGER environment variable: "less"
2018-08-29 13:06:14,813 (22759/MainThread) pgcli.main INFO - Default pager found in PAGER environment variable: "less"
2018-08-29 13:06:27,397 (22759/MainThread) pgcli.pgexecute ERROR - sql: u"select count(1) form users where role <> 'user'", error: ProgrammingError('syntax error at or near "users"\nLINE 1: select count(1) form users where role <> \'user\'\n                             ^\n',)
2018-08-29 13:06:27,399 (22759/MainThread) pgcli.pgexecute ERROR - traceback: 'Traceback (most recent call last):\n  File "/usr/local/Cellar/pgcli/1.9.1/libexec/lib/python2.7/site-packages/pgcli/pgexecute.py", line 319, in run\n    yield self.execute_normal_sql(sql) + (sql, True)\n  File "/usr/local/Cellar/pgcli/1.9.1/libexec/lib/python2.7/site-packages/pgcli/pgexecute.py", line 355, in execute_normal_sql\n    cur.execute(split_sql)\nProgrammingError: syntax error at or near "users"\nLINE 1: select count(1) form users where role <> \'user\'\n                             ^\n\n'
2018-08-29 13:06:36,803 (22759/MainThread) pgcli.pgexecute ERROR - sql: u"select count(1) from users where role <> 'user'", error: DataError('invalid input syntax for integer: "user"\nLINE 1: select count(1) from users where role <> \'user\'\n                                                 ^\n',)
2018-08-29 13:06:36,803 (22759/MainThread) pgcli.pgexecute ERROR - traceback: 'Traceback (most recent call last):\n  File "/usr/local/Cellar/pgcli/1.9.1/libexec/lib/python2.7/site-packages/pgcli/pgexecute.py", line 319, in run\n    yield self.execute_normal_sql(sql) + (sql, True)\n  File "/usr/local/Cellar/pgcli/1.9.1/libexec/lib/python2.7/site-packages/pgcli/pgexecute.py", line 355, in execute_normal_sql\n    cur.execute(split_sql)\nDataError: invalid input syntax for integer: "user"\nLINE 1: select count(1) from users where role <> \'user\'\n                                                 ^\n\n'
2018-08-29 13:06:42,468 (22759/MainThread) pgcli.pgexecute ERROR - sql: u"select count(1) from users where role != 'user'", error: DataError('invalid input syntax for integer: "user"\nLINE 1: select count(1) from users where role != \'user\'\n                                                 ^\n',)
2018-08-29 13:06:42,468 (22759/MainThread) pgcli.pgexecute ERROR - traceback: 'Traceback (most recent call last):\n  File "/usr/local/Cellar/pgcli/1.9.1/libexec/lib/python2.7/site-packages/pgcli/pgexecute.py", line 319, in run\n    yield self.execute_normal_sql(sql) + (sql, True)\n  File "/usr/local/Cellar/pgcli/1.9.1/libexec/lib/python2.7/site-packages/pgcli/pgexecute.py", line 355, in execute_normal_sql\n    cur.execute(split_sql)\nDataError: invalid input syntax for integer: "user"\nLINE 1: select count(1) from users where role != \'user\'\n                                                 ^\n\n'
2018-08-29 13:09:55,864 (22950/MainThread) pgcli.main INFO - Default pager found in PAGER environment variable: "less"
2018-08-29 13:09:55,914 (22950/MainThread) pgcli.main ERROR - traceback: 'Traceback (most recent call last):\n  File "/usr/local/Cellar/pgcli/1.9.1/libexec/lib/python2.7/site-packages/pgcli/main.py", line 416, in connect\n    raise e\nOperationalError: FATAL:  role "arthur" does not exist\n\n'
2018-08-29 13:10:00,888 (23075/MainThread) pgcli.main INFO - Default pager found in PAGER environment variable: "less"
2018-08-29 13:17:27,490 (23355/MainThread) pgcli.main INFO - Default pager found in PAGER environment variable: "less"
2018-08-30 08:54:40,035 (33503/MainThread) pgcli.main INFO - Default pager found in PAGER environment variable: "less"
2018-08-30 14:40:27,618 (42744/MainThread) pgcli.main INFO - Default pager found in PAGER environment variable: "less"
2018-08-30 16:37:52,381 (48712/MainThread) pgcli.main INFO - Default pager found in PAGER environment variable: "less"
2018-08-31 17:01:39,474 (91270/MainThread) pgcli.main INFO - Default pager found in PAGER environment variable: "less"
2018-09-03 10:24:15,905 (3715/MainThread) pgcli.main INFO - Default pager found in PAGER environment variable: "less"
2018-09-03 10:58:03,039 (5241/MainThread) pgcli.main INFO - Default pager found in PAGER environment variable: "less"
2018-09-03 11:21:31,812 (5241/MainThread) pgcli.pgexecute ERROR - sql: u'select\n  cm1.id,\n  cm1.conversation_participation_id,\n  cm1.created_at,\n  cm1.created_at - (select max(cm2.created_at) from conversation_messages cm2 where cp2.id = cm2.conversation_participation_id ahd cm2.created_at < cm1.created_at)\nfrom conversations c\ninner join conversation_participations cp1 on c.id = cp1.conversation_id and cp1.initiator = true\ninner join conversation_participations cp2 on c.id = cp2.conversation_id and cp2.initiator = false\ninner join conversation_messages cm1 on cp1.id = cm.conversation_participation_id\nwhere c.id = 74549\norder by cm.created_at', error: ProgrammingError('syntax error at or near "ahd"\nLINE 5: ... where cp2.id = cm2.conversation_participation_id ahd cm2.cr...\n                                                             ^\n',)
2018-09-03 11:21:31,813 (5241/MainThread) pgcli.pgexecute ERROR - traceback: 'Traceback (most recent call last):\n  File "/usr/local/Cellar/pgcli/1.9.1/libexec/lib/python2.7/site-packages/pgcli/pgexecute.py", line 319, in run\n    yield self.execute_normal_sql(sql) + (sql, True)\n  File "/usr/local/Cellar/pgcli/1.9.1/libexec/lib/python2.7/site-packages/pgcli/pgexecute.py", line 355, in execute_normal_sql\n    cur.execute(split_sql)\nProgrammingError: syntax error at or near "ahd"\nLINE 5: ... where cp2.id = cm2.conversation_participation_id ahd cm2.cr...\n                                                             ^\n\n'
2018-09-03 11:21:45,294 (5241/MainThread) pgcli.pgexecute ERROR - sql: u'select\n  cm1.id,\n  cm1.conversation_participation_id,\n  cm1.created_at,\n  cm1.created_at - (select max(cm2.created_at) from conversation_messages cm2 where cp2.id = cm2.conversation_participation_id and cm2.created_at < cm1.created_at)\nfrom conversations c\ninner join conversation_participations cp1 on c.id = cp1.conversation_id and cp1.initiator = true\ninner join conversation_participations cp2 on c.id = cp2.conversation_id and cp2.initiator = false\ninner join conversation_messages cm1 on cp1.id = cm.conversation_participation_id\nwhere c.id = 74549\norder by cm.created_at', error: ProgrammingError('missing FROM-clause entry for table "cm"\nLINE 9: inner join conversation_messages cm1 on cp1.id = cm.conversa...\n                                                         ^\n',)
2018-09-03 11:21:45,294 (5241/MainThread) pgcli.pgexecute ERROR - traceback: 'Traceback (most recent call last):\n  File "/usr/local/Cellar/pgcli/1.9.1/libexec/lib/python2.7/site-packages/pgcli/pgexecute.py", line 319, in run\n    yield self.execute_normal_sql(sql) + (sql, True)\n  File "/usr/local/Cellar/pgcli/1.9.1/libexec/lib/python2.7/site-packages/pgcli/pgexecute.py", line 355, in execute_normal_sql\n    cur.execute(split_sql)\nProgrammingError: missing FROM-clause entry for table "cm"\nLINE 9: inner join conversation_messages cm1 on cp1.id = cm.conversa...\n                                                         ^\n\n'
2018-09-03 11:23:50,466 (5241/MainThread) pgcli.pgexecute ERROR - sql: u'select average(responded_after) from (\n  select\n    cm1.id,\n    cm1.conversation_participation_id,\n    cm1.created_at,\n    cm1.created_at - (select max(cm2.created_at) from conversation_messages cm2 where cp2.id = cm2.conversation_participation_id and cm2.created_at < cm1.created_at) as responded_after\n  from conversations c\n  inner join conversation_participations cp1 on c.id = cp1.conversation_id and cp1.initiator = true\n  inner join conversation_participations cp2 on c.id = cp2.conversation_id and cp2.initiator = false\n  inner join conversation_messages cm1 on cp1.id = cm1.conversation_participation_id\n  where c.id = 74549\n  order by cm1.created_at\n)', error: ProgrammingError('subquery in FROM must have an alias\nLINE 1: select average(responded_after) from (\n                                             ^\nHINT:  For example, FROM (SELECT ...) [AS] foo.\n',)
2018-09-03 11:23:50,466 (5241/MainThread) pgcli.pgexecute ERROR - traceback: 'Traceback (most recent call last):\n  File "/usr/local/Cellar/pgcli/1.9.1/libexec/lib/python2.7/site-packages/pgcli/pgexecute.py", line 319, in run\n    yield self.execute_normal_sql(sql) + (sql, True)\n  File "/usr/local/Cellar/pgcli/1.9.1/libexec/lib/python2.7/site-packages/pgcli/pgexecute.py", line 355, in execute_normal_sql\n    cur.execute(split_sql)\nProgrammingError: subquery in FROM must have an alias\nLINE 1: select average(responded_after) from (\n                                             ^\nHINT:  For example, FROM (SELECT ...) [AS] foo.\n\n'
2018-09-03 11:24:05,739 (5241/MainThread) pgcli.pgexecute ERROR - sql: u'select average(sq.responded_after) from (\n  select\n    cm1.id,\n    cm1.conversation_participation_id,\n    cm1.created_at,\n    cm1.created_at - (select max(cm2.created_at) from conversation_messages cm2 where cp2.id = cm2.conversation_participation_id and cm2.created_at < cm1.created_at) as responded_after\n  from conversations c\n  inner join conversation_participations cp1 on c.id = cp1.conversation_id and cp1.initiator = true\n  inner join conversation_participations cp2 on c.id = cp2.conversation_id and cp2.initiator = false\n  inner join conversation_messages cm1 on cp1.id = cm1.conversation_participation_id\n  where c.id = 74549\n  order by cm1.created_at\n) sq', error: ProgrammingError('function average(interval) does not exist\nLINE 1: select average(sq.responded_after) from (\n               ^\nHINT:  No function matches the given name and argument types. You might need to add explicit type casts.\n',)
2018-09-03 11:24:05,739 (5241/MainThread) pgcli.pgexecute ERROR - traceback: 'Traceback (most recent call last):\n  File "/usr/local/Cellar/pgcli/1.9.1/libexec/lib/python2.7/site-packages/pgcli/pgexecute.py", line 319, in run\n    yield self.execute_normal_sql(sql) + (sql, True)\n  File "/usr/local/Cellar/pgcli/1.9.1/libexec/lib/python2.7/site-packages/pgcli/pgexecute.py", line 355, in execute_normal_sql\n    cur.execute(split_sql)\nProgrammingError: function average(interval) does not exist\nLINE 1: select average(sq.responded_after) from (\n               ^\nHINT:  No function matches the given name and argument types. You might need to add explicit type casts.\n\n'
2018-09-03 11:24:18,139 (5241/MainThread) pgcli.pgexecute ERROR - sql: u'select mean(sq.responded_after) from (\n  select\n    cm1.id,\n    cm1.conversation_participation_id,\n    cm1.created_at,\n    cm1.created_at - (select max(cm2.created_at) from conversation_messages cm2 where cp2.id = cm2.conversation_participation_id and cm2.created_at < cm1.created_at) as responded_after\n  from conversations c\n  inner join conversation_participations cp1 on c.id = cp1.conversation_id and cp1.initiator = true\n  inner join conversation_participations cp2 on c.id = cp2.conversation_id and cp2.initiator = false\n  inner join conversation_messages cm1 on cp1.id = cm1.conversation_participation_id\n  where c.id = 74549\n  order by cm1.created_at\n) sq', error: ProgrammingError('function mean(interval) does not exist\nLINE 1: select mean(sq.responded_after) from (\n               ^\nHINT:  No function matches the given name and argument types. You might need to add explicit type casts.\n',)
2018-09-03 11:24:18,139 (5241/MainThread) pgcli.pgexecute ERROR - traceback: 'Traceback (most recent call last):\n  File "/usr/local/Cellar/pgcli/1.9.1/libexec/lib/python2.7/site-packages/pgcli/pgexecute.py", line 319, in run\n    yield self.execute_normal_sql(sql) + (sql, True)\n  File "/usr/local/Cellar/pgcli/1.9.1/libexec/lib/python2.7/site-packages/pgcli/pgexecute.py", line 355, in execute_normal_sql\n    cur.execute(split_sql)\nProgrammingError: function mean(interval) does not exist\nLINE 1: select mean(sq.responded_after) from (\n               ^\nHINT:  No function matches the given name and argument types. You might need to add explicit type casts.\n\n'
2018-09-03 12:58:22,362 (8029/MainThread) pgcli.main INFO - Default pager found in PAGER environment variable: "less"
2018-09-03 15:28:27,145 (5241/MainThread) pgcli.pgexecute ERROR - sql: u"select count(1) from verification_address_verifications where verified_at between '2018-07-01' and '2018-07-31' and id_verifier_status = 'passed'", error: DataError('invalid input syntax for integer: "passed"\nLINE 1: ...18-07-01\' and \'2018-07-31\' and id_verifier_status = \'passed\'\n                                                               ^\n',)
2018-09-03 15:28:27,156 (5241/MainThread) pgcli.pgexecute ERROR - traceback: 'Traceback (most recent call last):\n  File "/usr/local/Cellar/pgcli/1.9.1/libexec/lib/python2.7/site-packages/pgcli/pgexecute.py", line 319, in run\n    yield self.execute_normal_sql(sql) + (sql, True)\n  File "/usr/local/Cellar/pgcli/1.9.1/libexec/lib/python2.7/site-packages/pgcli/pgexecute.py", line 355, in execute_normal_sql\n    cur.execute(split_sql)\nDataError: invalid input syntax for integer: "passed"\nLINE 1: ...18-07-01\' and \'2018-07-31\' and id_verifier_status = \'passed\'\n                                                               ^\n\n'
2018-09-06 09:54:29,225 (63754/MainThread) pgcli.main INFO - Default pager found in PAGER environment variable: "less"
2018-09-06 09:57:23,965 (63754/MainThread) pgcli.pgexecute ERROR - sql: u"select count(1) from verification_artifacts where type = 'binary/octet-stream'", error: ProgrammingError('column "type" does not exist\nLINE 1: select count(1) from verification_artifacts where type = \'bi...\n                                                          ^\n',)
2018-09-06 09:57:23,968 (63754/MainThread) pgcli.pgexecute ERROR - traceback: 'Traceback (most recent call last):\n  File "/usr/local/Cellar/pgcli/1.9.1/libexec/lib/python2.7/site-packages/pgcli/pgexecute.py", line 319, in run\n    yield self.execute_normal_sql(sql) + (sql, True)\n  File "/usr/local/Cellar/pgcli/1.9.1/libexec/lib/python2.7/site-packages/pgcli/pgexecute.py", line 355, in execute_normal_sql\n    cur.execute(split_sql)\nProgrammingError: column "type" does not exist\nLINE 1: select count(1) from verification_artifacts where type = \'bi...\n                                                          ^\n\n'
2018-09-06 10:05:56,945 (64315/MainThread) pgcli.main INFO - Default pager found in PAGER environment variable: "less"
2018-09-06 15:16:06,139 (5241/MainThread) pgcli.pgexecute ERROR - sql: u"select u.phone, u.uuid, coalesce(s.created_at, ''), 'blah' from users u left outer join subscriptions s on u.id = s.user_id where u.phone in ('01332989779',\n'07946523565',\n'07949148387',\n'07397576174',\n'07518318688',\n'07538922789',\n'01223571604',\n'07577763258',\n'07884416533',\n'07903421914',\n'02072740763',\n'07427677004',\n'07856338618',\n'07496572458',\n'07469248860',\n'07782249264',\n'07496572458')", error: DataError('invalid input syntax for type timestamp: ""\nLINE 1: select u.phone, u.uuid, coalesce(s.created_at, \'\'), \'blah\' f...\n                                                       ^\n',)
2018-09-06 15:16:06,140 (5241/MainThread) pgcli.pgexecute ERROR - traceback: 'Traceback (most recent call last):\n  File "/usr/local/Cellar/pgcli/1.9.1/libexec/lib/python2.7/site-packages/pgcli/pgexecute.py", line 319, in run\n    yield self.execute_normal_sql(sql) + (sql, True)\n  File "/usr/local/Cellar/pgcli/1.9.1/libexec/lib/python2.7/site-packages/pgcli/pgexecute.py", line 355, in execute_normal_sql\n    cur.execute(split_sql)\nDataError: invalid input syntax for type timestamp: ""\nLINE 1: select u.phone, u.uuid, coalesce(s.created_at, \'\'), \'blah\' f...\n                                                       ^\n\n'
2018-09-06 15:32:35,430 (5241/MainThread) pgcli.pgexecute ERROR - sql: u"select u.phone, u.uuid, s.created_at from users u left outer join subscriptions s on u.uid = s.user_id where u.phone in ('01380738245',\n'07709808902',\n'07522157755',\n'07803307706',\n'07557996070',\n'07974668721',\n'07554013714',\n'01293889614',\n'07763559401',\n'07754844609',\n'07968211874',\n'07495544858',\n'07980470816',\n'07973720447',\n'07916262870',\n'07808518134',\n'07795491018',\n'07958948549',\n'07879490487',\n'07809331200',\n'07845700983'\n)", error: ProgrammingError('column u.uid does not exist\nLINE 1: ...t from users u left outer join subscriptions s on u.uid = s....\n                                                             ^\n',)
2018-09-06 15:32:35,432 (5241/MainThread) pgcli.pgexecute ERROR - traceback: 'Traceback (most recent call last):\n  File "/usr/local/Cellar/pgcli/1.9.1/libexec/lib/python2.7/site-packages/pgcli/pgexecute.py", line 319, in run\n    yield self.execute_normal_sql(sql) + (sql, True)\n  File "/usr/local/Cellar/pgcli/1.9.1/libexec/lib/python2.7/site-packages/pgcli/pgexecute.py", line 355, in execute_normal_sql\n    cur.execute(split_sql)\nProgrammingError: column u.uid does not exist\nLINE 1: ...t from users u left outer join subscriptions s on u.uid = s....\n                                                             ^\n\n'
2018-09-07 08:57:48,287 (75384/MainThread) pgcli.main INFO - Default pager found in PAGER environment variable: "less"
2018-09-07 14:21:13,764 (5241/MainThread) pgcli.pgexecute ERROR - sql: u"drop extension 'fuzzystrmatch'", error: ProgrammingError('syntax error at or near "\'fuzzystrmatch\'"\nLINE 1: drop extension \'fuzzystrmatch\'\n                       ^\n',)
2018-09-07 14:21:13,766 (5241/MainThread) pgcli.pgexecute ERROR - traceback: 'Traceback (most recent call last):\n  File "/usr/local/Cellar/pgcli/1.9.1/libexec/lib/python2.7/site-packages/pgcli/pgexecute.py", line 319, in run\n    yield self.execute_normal_sql(sql) + (sql, True)\n  File "/usr/local/Cellar/pgcli/1.9.1/libexec/lib/python2.7/site-packages/pgcli/pgexecute.py", line 355, in execute_normal_sql\n    cur.execute(split_sql)\nProgrammingError: syntax error at or near "\'fuzzystrmatch\'"\nLINE 1: drop extension \'fuzzystrmatch\'\n                       ^\n\n'
2018-09-10 10:39:09,248 (5907/MainThread) pgcli.main INFO - Default pager found in PAGER environment variable: "less"
2018-09-11 13:20:14,348 (34968/MainThread) pgcli.main INFO - Default pager found in PAGER environment variable: "less"
2018-09-14 11:40:06,341 (5907/MainThread) pgcli.pgexecute ERROR - sql: u'select u.id, count(1) from users u inner join subscriptions s on u.id = s.user_id group by s.id having count(1) > 1 order by count(1) desc limit 10', error: ProgrammingError('column "u.id" must appear in the GROUP BY clause or be used in an aggregate function\nLINE 1: select u.id, count(1) from users u inner join subscriptions ...\n               ^\n',)
2018-09-14 11:40:06,344 (5907/MainThread) pgcli.pgexecute ERROR - traceback: 'Traceback (most recent call last):\n  File "/usr/local/Cellar/pgcli/1.9.1/libexec/lib/python2.7/site-packages/pgcli/pgexecute.py", line 319, in run\n    yield self.execute_normal_sql(sql) + (sql, True)\n  File "/usr/local/Cellar/pgcli/1.9.1/libexec/lib/python2.7/site-packages/pgcli/pgexecute.py", line 355, in execute_normal_sql\n    cur.execute(split_sql)\nProgrammingError: column "u.id" must appear in the GROUP BY clause or be used in an aggregate function\nLINE 1: select u.id, count(1) from users u inner join subscriptions ...\n               ^\n\n'
2018-09-14 11:43:56,819 (22041/MainThread) pgcli.main INFO - Default pager found in PAGER environment variable: "less"
2018-09-14 11:44:31,827 (22041/MainThread) pgcli.pgexecute ERROR - sql: u'u = User.find(686024)', error: ProgrammingError('syntax error at or near "u"\nLINE 1: u = User.find(686024)\n        ^\n',)
2018-09-14 11:44:31,828 (22041/MainThread) pgcli.pgexecute ERROR - traceback: 'Traceback (most recent call last):\n  File "/usr/local/Cellar/pgcli/1.9.1/libexec/lib/python2.7/site-packages/pgcli/pgexecute.py", line 319, in run\n    yield self.execute_normal_sql(sql) + (sql, True)\n  File "/usr/local/Cellar/pgcli/1.9.1/libexec/lib/python2.7/site-packages/pgcli/pgexecute.py", line 355, in execute_normal_sql\n    cur.execute(split_sql)\nProgrammingError: syntax error at or near "u"\nLINE 1: u = User.find(686024)\n        ^\n\n'
2018-09-17 10:27:45,801 (5084/MainThread) pgcli.main INFO - Default pager found in PAGER environment variable: "less"
2018-09-17 10:35:26,216 (5084/MainThread) pgcli.pgexecute ERROR - sql: u"'", error: ProgrammingError('unterminated quoted string at or near "\'"\nLINE 1: \'\n        ^\n',)
2018-09-17 10:35:26,217 (5084/MainThread) pgcli.pgexecute ERROR - traceback: 'Traceback (most recent call last):\n  File "/usr/local/Cellar/pgcli/1.9.1/libexec/lib/python2.7/site-packages/pgcli/pgexecute.py", line 319, in run\n    yield self.execute_normal_sql(sql) + (sql, True)\n  File "/usr/local/Cellar/pgcli/1.9.1/libexec/lib/python2.7/site-packages/pgcli/pgexecute.py", line 355, in execute_normal_sql\n    cur.execute(split_sql)\nProgrammingError: unterminated quoted string at or near "\'"\nLINE 1: \'\n        ^\n\n'
2018-09-17 11:13:26,757 (5084/MainThread) pgcli.pgexecute ERROR - sql: u"'", error: ProgrammingError('unterminated quoted string at or near "\'"\nLINE 1: \'\n        ^\n',)
2018-09-17 11:13:26,768 (5084/MainThread) pgcli.pgexecute ERROR - traceback: 'Traceback (most recent call last):\n  File "/usr/local/Cellar/pgcli/1.9.1/libexec/lib/python2.7/site-packages/pgcli/pgexecute.py", line 319, in run\n    yield self.execute_normal_sql(sql) + (sql, True)\n  File "/usr/local/Cellar/pgcli/1.9.1/libexec/lib/python2.7/site-packages/pgcli/pgexecute.py", line 355, in execute_normal_sql\n    cur.execute(split_sql)\nProgrammingError: unterminated quoted string at or near "\'"\nLINE 1: \'\n        ^\n\n'
2018-09-17 11:23:55,985 (5084/MainThread) pgcli.pgexecute ERROR - sql: u"select id, uuid, firstname, surname, ST_Distance(ST_GeographyFromText('SRID=4326;POINT(' || longitude || ' ' || latitude || ')'), location) / 1609.34 as distance from users order by distance limit 10", error: QueryCanceledError('canceling statement due to user request\n',)
2018-09-17 11:23:55,986 (5084/MainThread) pgcli.pgexecute ERROR - traceback: 'Traceback (most recent call last):\n  File "/usr/local/Cellar/pgcli/1.9.1/libexec/lib/python2.7/site-packages/pgcli/pgexecute.py", line 319, in run\n    yield self.execute_normal_sql(sql) + (sql, True)\n  File "/usr/local/Cellar/pgcli/1.9.1/libexec/lib/python2.7/site-packages/pgcli/pgexecute.py", line 355, in execute_normal_sql\n    cur.execute(split_sql)\nQueryCanceledError: canceling statement due to user request\n\n'
2018-09-17 11:23:55,987 (5084/MainThread) pgcli.main ERROR - sql: u"select id, uuid, firstname, surname, ST_Distance(ST_GeographyFromText('SRID=4326;POINT(' || longitude || ' ' || latitude || ')'), location) / 1609.34 as distance from users order by distance limit 10;", error: QueryCanceledError('canceling statement due to user request\n',)
2018-09-17 11:23:55,988 (5084/MainThread) pgcli.main ERROR - traceback: 'Traceback (most recent call last):\n  File "/usr/local/Cellar/pgcli/1.9.1/libexec/lib/python2.7/site-packages/pgcli/main.py", line 462, in execute_command\n    output, query = self._evaluate_command(text)\n  File "/usr/local/Cellar/pgcli/1.9.1/libexec/lib/python2.7/site-packages/pgcli/main.py", line 685, in _evaluate_command\n    for title, cur, headers, status, sql, success in res:\n  File "/usr/local/Cellar/pgcli/1.9.1/libexec/lib/python2.7/site-packages/pgcli/pgexecute.py", line 319, in run\n    yield self.execute_normal_sql(sql) + (sql, True)\n  File "/usr/local/Cellar/pgcli/1.9.1/libexec/lib/python2.7/site-packages/pgcli/pgexecute.py", line 355, in execute_normal_sql\n    cur.execute(split_sql)\nQueryCanceledError: canceling statement due to user request\n\n'
2018-09-20 08:58:29,980 (5084/MainThread) pgcli.pgexecute ERROR - sql: u'alter table users alter column tracking_id add not null', error: ProgrammingError('syntax error at or near "add"\nLINE 1: alter table users alter column tracking_id add not null\n                                                   ^\n',)
2018-09-20 08:58:29,985 (5084/MainThread) pgcli.pgexecute ERROR - traceback: 'Traceback (most recent call last):\n  File "/usr/local/Cellar/pgcli/1.9.1/libexec/lib/python2.7/site-packages/pgcli/pgexecute.py", line 319, in run\n    yield self.execute_normal_sql(sql) + (sql, True)\n  File "/usr/local/Cellar/pgcli/1.9.1/libexec/lib/python2.7/site-packages/pgcli/pgexecute.py", line 355, in execute_normal_sql\n    cur.execute(split_sql)\nProgrammingError: syntax error at or near "add"\nLINE 1: alter table users alter column tracking_id add not null\n                                                   ^\n\n'
2018-09-20 08:58:38,719 (5084/MainThread) pgcli.pgexecute ERROR - sql: u'alter table users alter column tracking_id not null', error: ProgrammingError('syntax error at or near "not"\nLINE 1: alter table users alter column tracking_id not null\n                                                   ^\n',)
2018-09-20 08:58:38,720 (5084/MainThread) pgcli.pgexecute ERROR - traceback: 'Traceback (most recent call last):\n  File "/usr/local/Cellar/pgcli/1.9.1/libexec/lib/python2.7/site-packages/pgcli/pgexecute.py", line 319, in run\n    yield self.execute_normal_sql(sql) + (sql, True)\n  File "/usr/local/Cellar/pgcli/1.9.1/libexec/lib/python2.7/site-packages/pgcli/pgexecute.py", line 355, in execute_normal_sql\n    cur.execute(split_sql)\nProgrammingError: syntax error at or near "not"\nLINE 1: alter table users alter column tracking_id not null\n                                                   ^\n\n'
2018-09-20 08:58:54,812 (5084/MainThread) pgcli.pgexecute ERROR - sql: u'alter table users alter column tracking_id set not null', error: IntegrityError('column "tracking_id" contains null values\n',)
2018-09-20 08:58:54,813 (5084/MainThread) pgcli.pgexecute ERROR - traceback: 'Traceback (most recent call last):\n  File "/usr/local/Cellar/pgcli/1.9.1/libexec/lib/python2.7/site-packages/pgcli/pgexecute.py", line 319, in run\n    yield self.execute_normal_sql(sql) + (sql, True)\n  File "/usr/local/Cellar/pgcli/1.9.1/libexec/lib/python2.7/site-packages/pgcli/pgexecute.py", line 355, in execute_normal_sql\n    cur.execute(split_sql)\nIntegrityError: column "tracking_id" contains null values\n\n'
2018-09-20 08:59:10,958 (5084/MainThread) pgcli.pgexecute ERROR - sql: u'update users set tracking_id = gen_uuid() where tracking_id is null', error: ProgrammingError('function gen_uuid() does not exist\nLINE 1: update users set tracking_id = gen_uuid() where tracking_id ...\n                                       ^\nHINT:  No function matches the given name and argument types. You might need to add explicit type casts.\n',)
2018-09-20 08:59:10,958 (5084/MainThread) pgcli.pgexecute ERROR - traceback: 'Traceback (most recent call last):\n  File "/usr/local/Cellar/pgcli/1.9.1/libexec/lib/python2.7/site-packages/pgcli/pgexecute.py", line 319, in run\n    yield self.execute_normal_sql(sql) + (sql, True)\n  File "/usr/local/Cellar/pgcli/1.9.1/libexec/lib/python2.7/site-packages/pgcli/pgexecute.py", line 355, in execute_normal_sql\n    cur.execute(split_sql)\nProgrammingError: function gen_uuid() does not exist\nLINE 1: update users set tracking_id = gen_uuid() where tracking_id ...\n                                       ^\nHINT:  No function matches the given name and argument types. You might need to add explicit type casts.\n\n'
2018-09-20 14:49:41,783 (5084/MainThread) pgcli.pgexecute ERROR - sql: u'select count(1) from conversation_unr', error: ProgrammingError('relation "conversation_unr" does not exist\nLINE 1: select count(1) from conversation_unr\n                             ^\n',)
2018-09-20 14:49:41,784 (5084/MainThread) pgcli.pgexecute ERROR - traceback: 'Traceback (most recent call last):\n  File "/usr/local/Cellar/pgcli/1.9.1/libexec/lib/python2.7/site-packages/pgcli/pgexecute.py", line 319, in run\n    yield self.execute_normal_sql(sql) + (sql, True)\n  File "/usr/local/Cellar/pgcli/1.9.1/libexec/lib/python2.7/site-packages/pgcli/pgexecute.py", line 355, in execute_normal_sql\n    cur.execute(split_sql)\nProgrammingError: relation "conversation_unr" does not exist\nLINE 1: select count(1) from conversation_unr\n                             ^\n\n'
2018-09-20 14:57:30,727 (5084/MainThread) pgcli.pgexecute ERROR - sql: u'select * from users u left outer join subscriptions s on u.id = s.user_id inner join conversation_participations cp on u.id = cp.user_id and cp.initiator = false', error: QueryCanceledError('canceling statement due to user request\n',)
2018-09-20 14:57:30,728 (5084/MainThread) pgcli.pgexecute ERROR - traceback: 'Traceback (most recent call last):\n  File "/usr/local/Cellar/pgcli/1.9.1/libexec/lib/python2.7/site-packages/pgcli/pgexecute.py", line 319, in run\n    yield self.execute_normal_sql(sql) + (sql, True)\n  File "/usr/local/Cellar/pgcli/1.9.1/libexec/lib/python2.7/site-packages/pgcli/pgexecute.py", line 355, in execute_normal_sql\n    cur.execute(split_sql)\nQueryCanceledError: canceling statement due to user request\n\n'
2018-09-20 14:57:30,728 (5084/MainThread) pgcli.main ERROR - sql: u'select * from users u left outer join subscriptions s on u.id = s.user_id inner join conversation_participations cp on u.id = cp.user_id and cp.initiator = false', error: QueryCanceledError('canceling statement due to user request\n',)
2018-09-20 14:57:30,730 (5084/MainThread) pgcli.main ERROR - traceback: 'Traceback (most recent call last):\n  File "/usr/local/Cellar/pgcli/1.9.1/libexec/lib/python2.7/site-packages/pgcli/main.py", line 462, in execute_command\n    output, query = self._evaluate_command(text)\n  File "/usr/local/Cellar/pgcli/1.9.1/libexec/lib/python2.7/site-packages/pgcli/main.py", line 685, in _evaluate_command\n    for title, cur, headers, status, sql, success in res:\n  File "/usr/local/Cellar/pgcli/1.9.1/libexec/lib/python2.7/site-packages/pgcli/pgexecute.py", line 319, in run\n    yield self.execute_normal_sql(sql) + (sql, True)\n  File "/usr/local/Cellar/pgcli/1.9.1/libexec/lib/python2.7/site-packages/pgcli/pgexecute.py", line 355, in execute_normal_sql\n    cur.execute(split_sql)\nQueryCanceledError: canceling statement due to user request\n\n'
2018-09-20 15:13:47,306 (5084/MainThread) pgcli.pgexecute ERROR - sql: u'select u.id, cp.id, cm.id, cum.id\n  from users u\n  left outer join subscriptions s on u.id = s.user_id\n  inner join conversation_participations cp1 on u.id = cp1.user_id and cp1.initiator = false\n  inner join conversation_participations cp2 on cp1.conversation_id = cp2.conversation_id and cp2.initiator = true\n  left outer join conversation_messages cm on cp2.id = cm.conversation_participation_id\n  left outer join conversation_unread_messages cum on u.id = cum.user_id and cp2.id = cum.conversation_participation_id and cm.id = cum.conversation_message_id\n  where u.id = 87309', error: ProgrammingError('missing FROM-clause entry for table "cp"\nLINE 1: select u.id, cp.id, cm.id, cum.id\n                     ^\n',)
2018-09-20 15:13:47,306 (5084/MainThread) pgcli.pgexecute ERROR - traceback: 'Traceback (most recent call last):\n  File "/usr/local/Cellar/pgcli/1.9.1/libexec/lib/python2.7/site-packages/pgcli/pgexecute.py", line 319, in run\n    yield self.execute_normal_sql(sql) + (sql, True)\n  File "/usr/local/Cellar/pgcli/1.9.1/libexec/lib/python2.7/site-packages/pgcli/pgexecute.py", line 355, in execute_normal_sql\n    cur.execute(split_sql)\nProgrammingError: missing FROM-clause entry for table "cp"\nLINE 1: select u.id, cp.id, cm.id, cum.id\n                     ^\n\n'
2018-09-20 15:15:34,997 (5084/MainThread) pgcli.pgexecute ERROR - sql: u'l', error: ProgrammingError('syntax error at or near "l"\nLINE 1: l\n        ^\n',)
2018-09-20 15:15:34,998 (5084/MainThread) pgcli.pgexecute ERROR - traceback: 'Traceback (most recent call last):\n  File "/usr/local/Cellar/pgcli/1.9.1/libexec/lib/python2.7/site-packages/pgcli/pgexecute.py", line 319, in run\n    yield self.execute_normal_sql(sql) + (sql, True)\n  File "/usr/local/Cellar/pgcli/1.9.1/libexec/lib/python2.7/site-packages/pgcli/pgexecute.py", line 355, in execute_normal_sql\n    cur.execute(split_sql)\nProgrammingError: syntax error at or near "l"\nLINE 1: l\n        ^\n\n'
2018-09-20 15:15:36,814 (5084/MainThread) pgcli.pgexecute ERROR - sql: u'```sql\nselect u.id, cp1.conversation_id, cp1.id, cp2.id, cm.id, cum.id\n  from users u\n  left outer join subscriptions s on u.id = s.user_id\n  inner join conversation_participations cp1 on u.id = cp1.user_id and cp1.initiator = false\n  inner join conversation_participations cp2 on cp1.conversation_id = cp2.conversation_id and cp2.initiator = true\n  left outer join conversation_messages cm on cp2.id = cm.conversation_participation_id\n  left outer join conversation_unread_messages cum on u.id = cum.user_id and cp1.id = cum.conversation_participation_id and cm.id = cum.conversation_message_id\n  where u.id = 87309', error: ProgrammingError('syntax error at or near "```"\nLINE 1: ```sql\n        ^\n',)
2018-09-20 15:15:36,815 (5084/MainThread) pgcli.pgexecute ERROR - traceback: 'Traceback (most recent call last):\n  File "/usr/local/Cellar/pgcli/1.9.1/libexec/lib/python2.7/site-packages/pgcli/pgexecute.py", line 319, in run\n    yield self.execute_normal_sql(sql) + (sql, True)\n  File "/usr/local/Cellar/pgcli/1.9.1/libexec/lib/python2.7/site-packages/pgcli/pgexecute.py", line 355, in execute_normal_sql\n    cur.execute(split_sql)\nProgrammingError: syntax error at or near "```"\nLINE 1: ```sql\n        ^\n\n'
2018-09-20 15:19:01,617 (5084/MainThread) pgcli.pgexecute ERROR - sql: u'select u.id, count(distinct cm.id) as received_message_count, count(distinct cum.id) as received_unread_message_count\n  from users u\n  left outer join subscriptions s on u.id = s.user_id\n  inner join conversation_participations cp1 on u.id = cp1.user_id and cp.initiator = false\n  inner join conversation_participations cp2 on cp1.conversation_id = cp2.conversation_id and cp2.initiator = true\n  inner join conversation_messages cm on cp2.id = cm.conversation_participation_id\n  left outer join conversation_unread_messages cum on u.id = cum.user_id and cp1.id = cum.conversation_participation_id and cm.id = cum.conversation_message_id\n  where s.id is null\n  group by u.id\n  having count(distinct cum.id) > 0\n  order by count(distinct cm.id) desc\n  limit 10', error: ProgrammingError('missing FROM-clause entry for table "cp"\nLINE 4: ...tion_participations cp1 on u.id = cp1.user_id and cp.initiat...\n                                                             ^\n',)
2018-09-20 15:19:01,618 (5084/MainThread) pgcli.pgexecute ERROR - traceback: 'Traceback (most recent call last):\n  File "/usr/local/Cellar/pgcli/1.9.1/libexec/lib/python2.7/site-packages/pgcli/pgexecute.py", line 319, in run\n    yield self.execute_normal_sql(sql) + (sql, True)\n  File "/usr/local/Cellar/pgcli/1.9.1/libexec/lib/python2.7/site-packages/pgcli/pgexecute.py", line 355, in execute_normal_sql\n    cur.execute(split_sql)\nProgrammingError: missing FROM-clause entry for table "cp"\nLINE 4: ...tion_participations cp1 on u.id = cp1.user_id and cp.initiat...\n                                                             ^\n\n'
2018-09-20 15:33:40,115 (5084/MainThread) pgcli.pgexecute ERROR - sql: u'select cm.* from conversation_messages cm inner join conversation_participations cp1 on cm.conversation_participation_id = cp1.id and cp1.initiator = false inner join conversation_participations cp2 on cp2.conversation_id = cp.conversation_id and cp2.initiator = true where cp1.user_id = 133827 order by cm.created_at desc limit 5', error: ProgrammingError('missing FROM-clause entry for table "cp"\nLINE 1: ...ation_participations cp2 on cp2.conversation_id = cp.convers...\n                                                             ^\n',)
2018-09-20 15:33:40,116 (5084/MainThread) pgcli.pgexecute ERROR - traceback: 'Traceback (most recent call last):\n  File "/usr/local/Cellar/pgcli/1.9.1/libexec/lib/python2.7/site-packages/pgcli/pgexecute.py", line 319, in run\n    yield self.execute_normal_sql(sql) + (sql, True)\n  File "/usr/local/Cellar/pgcli/1.9.1/libexec/lib/python2.7/site-packages/pgcli/pgexecute.py", line 355, in execute_normal_sql\n    cur.execute(split_sql)\nProgrammingError: missing FROM-clause entry for table "cp"\nLINE 1: ...ation_participations cp2 on cp2.conversation_id = cp.convers...\n                                                             ^\n\n'
2018-09-20 15:43:48,603 (5084/MainThread) pgcli.pgexecute ERROR - sql: u'select count(1) from user_identites', error: ProgrammingError('relation "user_identites" does not exist\nLINE 1: select count(1) from user_identites\n                             ^\n',)
2018-09-20 15:43:48,605 (5084/MainThread) pgcli.pgexecute ERROR - traceback: 'Traceback (most recent call last):\n  File "/usr/local/Cellar/pgcli/1.9.1/libexec/lib/python2.7/site-packages/pgcli/pgexecute.py", line 319, in run\n    yield self.execute_normal_sql(sql) + (sql, True)\n  File "/usr/local/Cellar/pgcli/1.9.1/libexec/lib/python2.7/site-packages/pgcli/pgexecute.py", line 355, in execute_normal_sql\n    cur.execute(split_sql)\nProgrammingError: relation "user_identites" does not exist\nLINE 1: select count(1) from user_identites\n                             ^\n\n'
2018-09-20 15:53:00,696 (64277/MainThread) pgcli.main INFO - Default pager found in PAGER environment variable: "less"
2018-09-24 10:31:13,905 (4551/MainThread) pgcli.main INFO - Default pager found in PAGER environment variable: "less"
